INFO 2024-01-14 21:16:48,667 autoreload 1732 1064 Watching for file changes with StatReloader
INFO 2024-01-14 21:16:52,462 basehttp 1732 10700 "GET / HTTP/1.1" 200 117
INFO 2024-01-14 21:16:54,207 basehttp 1732 10700 "GET / HTTP/1.1" 200 117
INFO 2024-01-14 21:24:51,973 autoreload 16736 22108 Watching for file changes with StatReloader
INFO 2024-01-17 19:18:52,250 autoreload 16736 22108 C:\Users\HUAWEI\OneDrive\Рабочий стол\e_store\e_store\mainapp\models.py changed, reloading.
INFO 2024-01-17 19:18:56,092 autoreload 22272 15792 Watching for file changes with StatReloader
INFO 2024-01-17 19:19:41,037 autoreload 22272 15792 C:\Users\HUAWEI\OneDrive\Рабочий стол\e_store\e_store\mainapp\models.py changed, reloading.
INFO 2024-01-17 19:19:41,794 autoreload 26924 22876 Watching for file changes with StatReloader
INFO 2024-01-18 19:52:09,073 autoreload 23532 27580 Watching for file changes with StatReloader
INFO 2024-01-18 19:52:10,845 basehttp 23532 22964 "GET / HTTP/1.1" 200 117
INFO 2024-01-18 19:52:29,962 basehttp 23532 19416 "GET /all_clients HTTP/1.1" 301 0
INFO 2024-01-18 19:52:29,971 basehttp 23532 14868 "GET /all_clients/ HTTP/1.1" 200 106
INFO 2024-01-24 10:49:03,191 autoreload 25464 1444 Watching for file changes with StatReloader
INFO 2024-01-24 10:49:07,525 basehttp 25464 13340 "GET / HTTP/1.1" 200 117
WARNING 2024-01-24 10:49:27,559 log 25464 27724 Not Found: /get_clients
WARNING 2024-01-24 10:49:27,559 basehttp 25464 27724 "GET /get_clients HTTP/1.1" 404 2783
INFO 2024-01-24 10:49:39,085 basehttp 25464 27724 "GET /all_clients HTTP/1.1" 301 0
INFO 2024-01-24 10:49:39,094 basehttp 25464 10796 "GET /all_clients/ HTTP/1.1" 200 106
INFO 2024-01-24 10:49:39,105 basehttp 25464 9900 - Broken pipe from ('127.0.0.1', 22685)
INFO 2024-01-24 10:52:37,290 autoreload 2324 4260 Watching for file changes with StatReloader
INFO 2024-01-24 10:52:39,898 basehttp 2324 1000 "GET /all_clients/ HTTP/1.1" 200 215
INFO 2024-01-24 11:01:00,265 autoreload 15532 6608 Watching for file changes with StatReloader
INFO 2024-01-24 11:01:03,284 basehttp 15532 29584 "GET /all_clients/ HTTP/1.1" 200 215
INFO 2024-01-24 11:01:25,960 basehttp 15532 29584 "GET /week HTTP/1.1" 301 0
ERROR 2024-01-24 11:01:26,117 log 15532 29476 Internal Server Error: /week/
Traceback (most recent call last):
  File "C:\Users\HUAWEI\OneDrive\Рабочий стол\e_store\venv\Lib\site-packages\django\core\handlers\exception.py", line 55, in inner
    response = get_response(request)
               ^^^^^^^^^^^^^^^^^^^^^
  File "C:\Users\HUAWEI\OneDrive\Рабочий стол\e_store\venv\Lib\site-packages\django\core\handlers\base.py", line 197, in _get_response
    response = wrapped_callback(request, *callback_args, **callback_kwargs)
               ^^^^^^^^^^^^^^^^^^^^^^^^^^^^^^^^^^^^^^^^^^^^^^^^^^^^^^^^^^^^
  File "C:\Users\HUAWEI\OneDrive\Рабочий стол\e_store\e_store\mainapp\views.py", line 32, in show_sorted_orders
    context['orders'] = Order.objects.filter(date_ordered__gte=date(d.year, d.month, d.day))
                                                               ^^^^^^^^^^^^^^^^^^^^^^^^^^^^
TypeError: date() takes from 1 to 2 positional arguments but 3 were given
ERROR 2024-01-24 11:01:26,119 basehttp 15532 29476 "GET /week/ HTTP/1.1" 500 64994
INFO 2024-01-24 11:02:24,037 autoreload 15532 6608 C:\Users\HUAWEI\OneDrive\Рабочий стол\e_store\e_store\mainapp\views.py changed, reloading.
INFO 2024-01-24 11:02:24,700 autoreload 18608 26876 Watching for file changes with StatReloader
ERROR 2024-01-24 11:02:25,692 log 18608 16972 Internal Server Error: /week/
Traceback (most recent call last):
  File "C:\Users\HUAWEI\OneDrive\Рабочий стол\e_store\venv\Lib\site-packages\django\core\handlers\exception.py", line 55, in inner
    response = get_response(request)
               ^^^^^^^^^^^^^^^^^^^^^
  File "C:\Users\HUAWEI\OneDrive\Рабочий стол\e_store\venv\Lib\site-packages\django\core\handlers\base.py", line 197, in _get_response
    response = wrapped_callback(request, *callback_args, **callback_kwargs)
               ^^^^^^^^^^^^^^^^^^^^^^^^^^^^^^^^^^^^^^^^^^^^^^^^^^^^^^^^^^^^
  File "C:\Users\HUAWEI\OneDrive\Рабочий стол\e_store\e_store\mainapp\views.py", line 32, in show_sorted_orders
    context['orders'] = Order.objects.filter(date_ordered__gte=d)
                        ^^^^^^^^^^^^^^^^^^^^^^^^^^^^^^^^^^^^^^^^^
  File "C:\Users\HUAWEI\OneDrive\Рабочий стол\e_store\venv\Lib\site-packages\django\db\models\manager.py", line 87, in manager_method
    return getattr(self.get_queryset(), name)(*args, **kwargs)
           ^^^^^^^^^^^^^^^^^^^^^^^^^^^^^^^^^^^^^^^^^^^^^^^^^^^
  File "C:\Users\HUAWEI\OneDrive\Рабочий стол\e_store\venv\Lib\site-packages\django\db\models\query.py", line 1436, in filter
    return self._filter_or_exclude(False, args, kwargs)
           ^^^^^^^^^^^^^^^^^^^^^^^^^^^^^^^^^^^^^^^^^^^^
  File "C:\Users\HUAWEI\OneDrive\Рабочий стол\e_store\venv\Lib\site-packages\django\db\models\query.py", line 1454, in _filter_or_exclude
    clone._filter_or_exclude_inplace(negate, args, kwargs)
  File "C:\Users\HUAWEI\OneDrive\Рабочий стол\e_store\venv\Lib\site-packages\django\db\models\query.py", line 1461, in _filter_or_exclude_inplace
    self._query.add_q(Q(*args, **kwargs))
  File "C:\Users\HUAWEI\OneDrive\Рабочий стол\e_store\venv\Lib\site-packages\django\db\models\sql\query.py", line 1546, in add_q
    clause, _ = self._add_q(q_object, self.used_aliases)
                ^^^^^^^^^^^^^^^^^^^^^^^^^^^^^^^^^^^^^^^^
  File "C:\Users\HUAWEI\OneDrive\Рабочий стол\e_store\venv\Lib\site-packages\django\db\models\sql\query.py", line 1577, in _add_q
    child_clause, needed_inner = self.build_filter(
                                 ^^^^^^^^^^^^^^^^^^
  File "C:\Users\HUAWEI\OneDrive\Рабочий стол\e_store\venv\Lib\site-packages\django\db\models\sql\query.py", line 1427, in build_filter
    lookups, parts, reffed_expression = self.solve_lookup_type(arg, summarize)
                                        ^^^^^^^^^^^^^^^^^^^^^^^^^^^^^^^^^^^^^^
  File "C:\Users\HUAWEI\OneDrive\Рабочий стол\e_store\venv\Lib\site-packages\django\db\models\sql\query.py", line 1237, in solve_lookup_type
    _, field, _, lookup_parts = self.names_to_path(lookup_splitted, self.get_meta())
                                ^^^^^^^^^^^^^^^^^^^^^^^^^^^^^^^^^^^^^^^^^^^^^^^^^^^^
  File "C:\Users\HUAWEI\OneDrive\Рабочий стол\e_store\venv\Lib\site-packages\django\db\models\sql\query.py", line 1725, in names_to_path
    raise FieldError(
django.core.exceptions.FieldError: Cannot resolve keyword 'date_ordered' into field. Choices are: client_id, client_id_id, date, goods, id, total_price
ERROR 2024-01-24 11:02:25,692 basehttp 18608 16972 "GET /week/ HTTP/1.1" 500 110715
INFO 2024-01-24 11:02:55,530 autoreload 18608 26876 C:\Users\HUAWEI\OneDrive\Рабочий стол\e_store\e_store\mainapp\views.py changed, reloading.
INFO 2024-01-24 11:02:56,209 autoreload 3164 27564 Watching for file changes with StatReloader
ERROR 2024-01-24 11:02:57,558 log 3164 5152 Internal Server Error: /week/
Traceback (most recent call last):
  File "C:\Users\HUAWEI\OneDrive\Рабочий стол\e_store\venv\Lib\site-packages\django\core\handlers\exception.py", line 55, in inner
    response = get_response(request)
               ^^^^^^^^^^^^^^^^^^^^^
  File "C:\Users\HUAWEI\OneDrive\Рабочий стол\e_store\venv\Lib\site-packages\django\core\handlers\base.py", line 197, in _get_response
    response = wrapped_callback(request, *callback_args, **callback_kwargs)
               ^^^^^^^^^^^^^^^^^^^^^^^^^^^^^^^^^^^^^^^^^^^^^^^^^^^^^^^^^^^^
  File "C:\Users\HUAWEI\OneDrive\Рабочий стол\e_store\e_store\mainapp\views.py", line 33, in show_sorted_orders
    return render(request, 'main/sorted_orders.html', context)
           ^^^^^^^^^^^^^^^^^^^^^^^^^^^^^^^^^^^^^^^^^^^^^^^^^^^
  File "C:\Users\HUAWEI\OneDrive\Рабочий стол\e_store\venv\Lib\site-packages\django\shortcuts.py", line 24, in render
    content = loader.render_to_string(template_name, context, request, using=using)
              ^^^^^^^^^^^^^^^^^^^^^^^^^^^^^^^^^^^^^^^^^^^^^^^^^^^^^^^^^^^^^^^^^^^^^
  File "C:\Users\HUAWEI\OneDrive\Рабочий стол\e_store\venv\Lib\site-packages\django\template\loader.py", line 61, in render_to_string
    template = get_template(template_name, using=using)
               ^^^^^^^^^^^^^^^^^^^^^^^^^^^^^^^^^^^^^^^^
  File "C:\Users\HUAWEI\OneDrive\Рабочий стол\e_store\venv\Lib\site-packages\django\template\loader.py", line 19, in get_template
    raise TemplateDoesNotExist(template_name, chain=chain)
django.template.exceptions.TemplateDoesNotExist: main/sorted_orders.html
ERROR 2024-01-24 11:02:57,568 basehttp 3164 5152 "GET /week/ HTTP/1.1" 500 80255
INFO 2024-01-24 11:05:01,928 autoreload 3164 27564 C:\Users\HUAWEI\OneDrive\Рабочий стол\e_store\e_store\mainapp\views.py changed, reloading.
INFO 2024-01-24 11:05:02,599 autoreload 600 8972 Watching for file changes with StatReloader
INFO 2024-01-24 11:08:02,296 basehttp 600 26876 "GET /week/ HTTP/1.1" 200 327
INFO 2024-01-24 11:18:42,398 autoreload 13884 16640 Watching for file changes with StatReloader
INFO 2024-01-24 11:18:56,228 basehttp 13884 13788 "GET /all_clients/ HTTP/1.1" 200 215
INFO 2024-01-24 19:46:38,279 autoreload 7216 28660 Watching for file changes with StatReloader
INFO 2024-01-24 19:46:41,824 basehttp 7216 26248 "GET / HTTP/1.1" 200 117
INFO 2024-01-24 19:46:48,473 basehttp 7216 13512 "GET /week HTTP/1.1" 301 0
INFO 2024-01-24 19:46:48,498 basehttp 7216 14280 "GET /week/ HTTP/1.1" 200 327
INFO 2024-01-24 19:54:28,780 autoreload 7216 28660 C:\Users\HUAWEI\OneDrive\Рабочий стол\e_store\e_store\mainapp\views.py changed, reloading.
INFO 2024-01-24 19:54:29,541 autoreload 28448 29228 Watching for file changes with StatReloader
WARNING 2024-01-24 19:55:00,363 log 28448 8244 Not Found: /get_orders
WARNING 2024-01-24 19:55:00,364 basehttp 28448 8244 "GET /get_orders HTTP/1.1" 404 2949
INFO 2024-01-24 19:55:31,487 basehttp 28448 13368 "GET /orders HTTP/1.1" 301 0
INFO 2024-01-24 19:55:31,500 basehttp 28448 11844 "GET /orders/ HTTP/1.1" 200 176
INFO 2024-01-24 20:01:03,353 autoreload 2632 5656 Watching for file changes with StatReloader
INFO 2024-01-24 20:01:12,057 basehttp 2632 15420 "GET /orders/ HTTP/1.1" 200 271
INFO 2024-01-24 20:01:18,182 basehttp 2632 9732 "GET /week/ HTTP/1.1" 200 329
INFO 2024-01-24 20:06:05,801 basehttp 2632 10880 "GET /week/ HTTP/1.1" 200 323
INFO 2024-01-24 20:09:05,599 basehttp 2632 20108 "GET / HTTP/1.1" 200 117
INFO 2024-01-24 20:09:13,830 basehttp 2632 20108 "GET /orders/ HTTP/1.1" 200 265
INFO 2024-01-24 20:10:11,156 basehttp 2632 24052 "GET /week/ HTTP/1.1" 200 323
INFO 2024-01-24 20:17:05,099 basehttp 2632 12564 "GET /week/ HTTP/1.1" 200 323
INFO 2024-01-24 20:23:23,517 autoreload 2632 5656 C:\Users\HUAWEI\OneDrive\Рабочий стол\e_store\e_store\mainapp\views.py changed, reloading.
INFO 2024-01-24 20:23:24,265 autoreload 26984 28984 Watching for file changes with StatReloader
INFO 2024-01-24 20:26:29,598 autoreload 26984 28984 C:\Users\HUAWEI\OneDrive\Рабочий стол\e_store\e_store\mainapp\views.py changed, reloading.
INFO 2024-01-24 20:26:30,179 autoreload 25824 1632 Watching for file changes with StatReloader
INFO 2024-01-24 20:27:03,137 basehttp 25824 13616 "GET /week/ HTTP/1.1" 200 323
INFO 2024-01-24 20:27:05,053 basehttp 25824 13616 "GET / HTTP/1.1" 200 117
INFO 2024-01-24 20:27:20,842 basehttp 25824 9636 "GET /orders/ HTTP/1.1" 200 265
INFO 2024-01-24 20:27:59,838 basehttp 25824 4720 "GET /all_clients HTTP/1.1" 301 0
INFO 2024-01-24 20:27:59,846 basehttp 25824 27916 "GET /all_clients/ HTTP/1.1" 200 215
INFO 2024-01-24 20:28:10,331 basehttp 25824 18180 "GET /week/ HTTP/1.1" 200 323
INFO 2024-01-24 20:31:58,667 autoreload 25824 1632 C:\Users\HUAWEI\OneDrive\Рабочий стол\e_store\e_store\mainapp\views.py changed, reloading.
INFO 2024-01-24 20:31:59,286 autoreload 3056 27588 Watching for file changes with StatReloader
INFO 2024-01-24 20:32:00,468 basehttp 3056 17732 "GET /week/ HTTP/1.1" 200 174
INFO 2024-01-24 20:32:51,090 autoreload 3056 27588 C:\Users\HUAWEI\OneDrive\Рабочий стол\e_store\e_store\mainapp\views.py changed, reloading.
INFO 2024-01-24 20:32:51,700 autoreload 26904 14620 Watching for file changes with StatReloader
INFO 2024-01-24 20:32:52,227 basehttp 26904 9508 "GET /week/ HTTP/1.1" 200 178
INFO 2024-01-24 20:36:41,454 autoreload 9340 17112 Watching for file changes with StatReloader
INFO 2024-01-24 20:36:44,105 basehttp 9340 18756 "GET /week/ HTTP/1.1" 200 272
INFO 2024-01-24 20:38:27,007 autoreload 9340 17112 C:\Users\HUAWEI\OneDrive\Рабочий стол\e_store\e_store\mainapp\views.py changed, reloading.
INFO 2024-01-24 20:38:27,626 autoreload 22144 14140 Watching for file changes with StatReloader
INFO 2024-01-24 20:38:28,946 basehttp 22144 26036 "GET /week/ HTTP/1.1" 200 330
INFO 2024-01-24 20:38:53,880 basehttp 22144 17844 "GET /week/ HTTP/1.1" 200 324
INFO 2024-01-24 20:38:53,894 basehttp 22144 14096 - Broken pipe from ('127.0.0.1', 29979)
INFO 2024-01-24 20:40:37,099 basehttp 22144 23696 "GET /week/ HTTP/1.1" 200 318
INFO 2024-01-24 20:41:20,295 autoreload 22144 14140 C:\Users\HUAWEI\OneDrive\Рабочий стол\e_store\e_store\mainapp\views.py changed, reloading.
INFO 2024-01-24 20:41:20,796 autoreload 29116 11312 Watching for file changes with StatReloader
INFO 2024-01-24 20:47:10,359 autoreload 29116 11312 C:\Users\HUAWEI\OneDrive\Рабочий стол\e_store\e_store\mainapp\views.py changed, reloading.
INFO 2024-01-24 20:47:10,946 autoreload 21792 29448 Watching for file changes with StatReloader
INFO 2024-01-24 20:47:52,509 autoreload 21792 29448 C:\Users\HUAWEI\OneDrive\Рабочий стол\e_store\e_store\mainapp\views.py changed, reloading.
INFO 2024-01-24 20:47:53,004 autoreload 8484 16036 Watching for file changes with StatReloader
INFO 2024-01-24 20:48:27,361 autoreload 8484 16036 C:\Users\HUAWEI\OneDrive\Рабочий стол\e_store\e_store\mainapp\views.py changed, reloading.
INFO 2024-01-24 20:48:27,972 autoreload 23768 14868 Watching for file changes with StatReloader
INFO 2024-01-24 20:49:07,271 autoreload 23768 14868 C:\Users\HUAWEI\OneDrive\Рабочий стол\e_store\e_store\mainapp\urls.py changed, reloading.
INFO 2024-01-24 20:49:07,798 autoreload 9512 3120 Watching for file changes with StatReloader
INFO 2024-01-24 20:52:38,511 autoreload 9512 3120 C:\Users\HUAWEI\OneDrive\Рабочий стол\e_store\e_store\mainapp\urls.py changed, reloading.
INFO 2024-01-24 20:52:39,184 autoreload 6776 572 Watching for file changes with StatReloader
INFO 2024-01-24 20:53:54,410 autoreload 6776 572 C:\Users\HUAWEI\OneDrive\Рабочий стол\e_store\e_store\mainapp\urls.py changed, reloading.
INFO 2024-01-24 20:53:54,978 autoreload 26672 17536 Watching for file changes with StatReloader
INFO 2024-01-24 20:56:06,149 autoreload 9952 9068 Watching for file changes with StatReloader
INFO 2024-01-24 20:56:08,580 basehttp 9952 16024 "GET / HTTP/1.1" 200 117
INFO 2024-01-24 20:56:20,100 basehttp 9952 16024 "GET /orders/1 HTTP/1.1" 301 0
INFO 2024-01-24 20:56:20,116 basehttp 9952 19632 "GET /orders/1/ HTTP/1.1" 200 226
INFO 2024-01-24 20:56:27,171 basehttp 9952 19632 "GET /orders/0 HTTP/1.1" 301 0
INFO 2024-01-24 20:56:27,180 basehttp 9952 12868 "GET /orders/0/ HTTP/1.1" 200 226
INFO 2024-01-24 20:58:29,412 basehttp 9952 12868 "GET /orders/1/ HTTP/1.1" 200 220
INFO 2024-01-24 21:01:45,595 basehttp 9952 12868 "GET /orders/1/ HTTP/1.1" 200 220
INFO 2024-01-25 17:22:51,970 basehttp 9952 11848 - Broken pipe from ('127.0.0.1', 32245)
INFO 2024-01-25 17:23:11,165 autoreload 9952 9068 C:\Users\HUAWEI\OneDrive\Рабочий стол\e_store\e_store\mainapp\views.py changed, reloading.
INFO 2024-01-25 17:23:13,251 autoreload 9972 8232 Watching for file changes with StatReloader
INFO 2024-01-25 17:26:58,143 autoreload 9972 8232 C:\Users\HUAWEI\OneDrive\Рабочий стол\e_store\e_store\mainapp\views.py changed, reloading.
INFO 2024-01-25 17:26:58,917 autoreload 19164 19400 Watching for file changes with StatReloader
INFO 2024-01-25 17:33:36,049 autoreload 19164 19400 C:\Users\HUAWEI\OneDrive\Рабочий стол\e_store\e_store\mainapp\views.py changed, reloading.
INFO 2024-01-25 17:33:36,682 autoreload 14924 26236 Watching for file changes with StatReloader
ERROR 2024-01-25 17:33:41,641 log 14924 24012 Internal Server Error: /orders/1/
Traceback (most recent call last):
  File "C:\Users\HUAWEI\OneDrive\Рабочий стол\e_store\venv\Lib\site-packages\django\core\handlers\exception.py", line 55, in inner
    response = get_response(request)
               ^^^^^^^^^^^^^^^^^^^^^
  File "C:\Users\HUAWEI\OneDrive\Рабочий стол\e_store\venv\Lib\site-packages\django\core\handlers\base.py", line 197, in _get_response
    response = wrapped_callback(request, *callback_args, **callback_kwargs)
               ^^^^^^^^^^^^^^^^^^^^^^^^^^^^^^^^^^^^^^^^^^^^^^^^^^^^^^^^^^^^
  File "C:\Users\HUAWEI\OneDrive\Рабочий стол\e_store\e_store\mainapp\views.py", line 25, in get_orders
    return render(request, 'mainapp/sorted_orders.html', {'orders': orders})
           ^^^^^^^^^^^^^^^^^^^^^^^^^^^^^^^^^^^^^^^^^^^^^^^^^^^^^^^^^^^^^^^^^
  File "C:\Users\HUAWEI\OneDrive\Рабочий стол\e_store\venv\Lib\site-packages\django\shortcuts.py", line 24, in render
    content = loader.render_to_string(template_name, context, request, using=using)
              ^^^^^^^^^^^^^^^^^^^^^^^^^^^^^^^^^^^^^^^^^^^^^^^^^^^^^^^^^^^^^^^^^^^^^
  File "C:\Users\HUAWEI\OneDrive\Рабочий стол\e_store\venv\Lib\site-packages\django\template\loader.py", line 61, in render_to_string
    template = get_template(template_name, using=using)
               ^^^^^^^^^^^^^^^^^^^^^^^^^^^^^^^^^^^^^^^^
  File "C:\Users\HUAWEI\OneDrive\Рабочий стол\e_store\venv\Lib\site-packages\django\template\loader.py", line 19, in get_template
    raise TemplateDoesNotExist(template_name, chain=chain)
django.template.exceptions.TemplateDoesNotExist: mainapp/sorted_orders.html
ERROR 2024-01-25 17:33:41,643 basehttp 14924 24012 "GET /orders/1/ HTTP/1.1" 500 81541
INFO 2024-01-25 17:33:44,610 basehttp 14924 24012 "GET / HTTP/1.1" 200 117
INFO 2024-01-25 17:33:57,847 basehttp 14924 24012 "GET /client_orders/1 HTTP/1.1" 301 0
ERROR 2024-01-25 17:33:57,877 log 14924 12236 Internal Server Error: /client_orders/1/
Traceback (most recent call last):
  File "C:\Users\HUAWEI\OneDrive\Рабочий стол\e_store\venv\Lib\site-packages\django\core\handlers\exception.py", line 55, in inner
    response = get_response(request)
               ^^^^^^^^^^^^^^^^^^^^^
  File "C:\Users\HUAWEI\OneDrive\Рабочий стол\e_store\venv\Lib\site-packages\django\core\handlers\base.py", line 197, in _get_response
    response = wrapped_callback(request, *callback_args, **callback_kwargs)
               ^^^^^^^^^^^^^^^^^^^^^^^^^^^^^^^^^^^^^^^^^^^^^^^^^^^^^^^^^^^^
  File "C:\Users\HUAWEI\OneDrive\Рабочий стол\e_store\e_store\mainapp\views.py", line 35, in get_client_orders
    return render(request, 'mainapp/orders_goods.html', {'orders': orders, 'goods': orders.goods})
                                                                                    ^^^^^^^^^^^^
AttributeError: 'QuerySet' object has no attribute 'goods'
ERROR 2024-01-25 17:33:57,878 basehttp 14924 12236 "GET /client_orders/1/ HTTP/1.1" 500 65148
INFO 2024-01-25 17:39:26,176 autoreload 14924 26236 C:\Users\HUAWEI\OneDrive\Рабочий стол\e_store\e_store\mainapp\views.py changed, reloading.
INFO 2024-01-25 17:39:26,716 autoreload 11848 29252 Watching for file changes with StatReloader
INFO 2024-01-25 17:40:11,854 autoreload 11848 29252 C:\Users\HUAWEI\OneDrive\Рабочий стол\e_store\e_store\mainapp\views.py changed, reloading.
INFO 2024-01-25 17:40:12,379 autoreload 28756 600 Watching for file changes with StatReloader
INFO 2024-01-25 17:40:19,850 basehttp 28756 23912 "GET /client_orders/1/ HTTP/1.1" 200 124
INFO 2024-01-25 17:40:38,471 basehttp 28756 23912 "GET /client_orders/4 HTTP/1.1" 301 0
INFO 2024-01-25 17:40:38,482 basehttp 28756 13720 "GET /client_orders/4/ HTTP/1.1" 200 230
INFO 2024-01-25 17:41:31,372 autoreload 28756 600 C:\Users\HUAWEI\OneDrive\Рабочий стол\e_store\e_store\mainapp\views.py changed, reloading.
INFO 2024-01-25 17:41:31,878 autoreload 26292 8656 Watching for file changes with StatReloader
INFO 2024-01-25 17:43:55,935 autoreload 26292 8656 C:\Users\HUAWEI\OneDrive\Рабочий стол\e_store\e_store\mainapp\views.py changed, reloading.
INFO 2024-01-25 17:43:56,461 autoreload 28268 27056 Watching for file changes with StatReloader
INFO 2024-01-25 17:43:57,227 basehttp 28268 13680 "GET /client_orders/4/ HTTP/1.1" 200 320
INFO 2024-01-25 17:50:16,153 autoreload 28268 27056 C:\Users\HUAWEI\OneDrive\Рабочий стол\e_store\e_store\mainapp\views.py changed, reloading.
INFO 2024-01-25 17:50:16,930 autoreload 29380 1320 Watching for file changes with StatReloader
ERROR 2024-01-25 17:50:19,490 log 29380 29536 Internal Server Error: /client_orders/4/
Traceback (most recent call last):
  File "C:\Users\HUAWEI\OneDrive\Рабочий стол\e_store\venv\Lib\site-packages\django\core\handlers\exception.py", line 55, in inner
    response = get_response(request)
               ^^^^^^^^^^^^^^^^^^^^^
  File "C:\Users\HUAWEI\OneDrive\Рабочий стол\e_store\venv\Lib\site-packages\django\core\handlers\base.py", line 197, in _get_response
    response = wrapped_callback(request, *callback_args, **callback_kwargs)
               ^^^^^^^^^^^^^^^^^^^^^^^^^^^^^^^^^^^^^^^^^^^^^^^^^^^^^^^^^^^^
  File "C:\Users\HUAWEI\OneDrive\Рабочий стол\e_store\e_store\mainapp\views.py", line 36, in get_client_orders
    for good in orders:
TypeError: 'Order' object is not iterable
ERROR 2024-01-25 17:50:19,491 basehttp 29380 29536 "GET /client_orders/4/ HTTP/1.1" 500 65465
INFO 2024-01-25 17:50:45,302 autoreload 29380 1320 C:\Users\HUAWEI\OneDrive\Рабочий стол\e_store\e_store\mainapp\views.py changed, reloading.
INFO 2024-01-25 17:50:45,878 autoreload 25240 16168 Watching for file changes with StatReloader
INFO 2024-01-25 17:51:11,891 autoreload 25240 16168 C:\Users\HUAWEI\OneDrive\Рабочий стол\e_store\e_store\mainapp\views.py changed, reloading.
INFO 2024-01-25 17:51:12,382 autoreload 27904 28960 Watching for file changes with StatReloader
ERROR 2024-01-25 17:51:12,671 log 27904 21896 Internal Server Error: /client_orders/4/
Traceback (most recent call last):
  File "C:\Users\HUAWEI\OneDrive\Рабочий стол\e_store\venv\Lib\site-packages\django\core\handlers\exception.py", line 55, in inner
    response = get_response(request)
               ^^^^^^^^^^^^^^^^^^^^^
  File "C:\Users\HUAWEI\OneDrive\Рабочий стол\e_store\venv\Lib\site-packages\django\core\handlers\base.py", line 197, in _get_response
    response = wrapped_callback(request, *callback_args, **callback_kwargs)
               ^^^^^^^^^^^^^^^^^^^^^^^^^^^^^^^^^^^^^^^^^^^^^^^^^^^^^^^^^^^^
  File "C:\Users\HUAWEI\OneDrive\Рабочий стол\e_store\e_store\mainapp\views.py", line 36, in get_client_orders
    return render(request, 'mainapp/orders_goods.html', {'orders': orders})
           ^^^^^^^^^^^^^^^^^^^^^^^^^^^^^^^^^^^^^^^^^^^^^^^^^^^^^^^^^^^^^^^^
  File "C:\Users\HUAWEI\OneDrive\Рабочий стол\e_store\venv\Lib\site-packages\django\shortcuts.py", line 24, in render
    content = loader.render_to_string(template_name, context, request, using=using)
              ^^^^^^^^^^^^^^^^^^^^^^^^^^^^^^^^^^^^^^^^^^^^^^^^^^^^^^^^^^^^^^^^^^^^^
  File "C:\Users\HUAWEI\OneDrive\Рабочий стол\e_store\venv\Lib\site-packages\django\template\loader.py", line 62, in render_to_string
    return template.render(context, request)
           ^^^^^^^^^^^^^^^^^^^^^^^^^^^^^^^^^
  File "C:\Users\HUAWEI\OneDrive\Рабочий стол\e_store\venv\Lib\site-packages\django\template\backends\django.py", line 61, in render
    return self.template.render(context)
           ^^^^^^^^^^^^^^^^^^^^^^^^^^^^^
  File "C:\Users\HUAWEI\OneDrive\Рабочий стол\e_store\venv\Lib\site-packages\django\template\base.py", line 175, in render
    return self._render(context)
           ^^^^^^^^^^^^^^^^^^^^^
  File "C:\Users\HUAWEI\OneDrive\Рабочий стол\e_store\venv\Lib\site-packages\django\template\base.py", line 167, in _render
    return self.nodelist.render(context)
           ^^^^^^^^^^^^^^^^^^^^^^^^^^^^^
  File "C:\Users\HUAWEI\OneDrive\Рабочий стол\e_store\venv\Lib\site-packages\django\template\base.py", line 1005, in render
    return SafeString("".join([node.render_annotated(context) for node in self]))
                              ^^^^^^^^^^^^^^^^^^^^^^^^^^^^^^^^^^^^^^^^^^^^^^^^^
  File "C:\Users\HUAWEI\OneDrive\Рабочий стол\e_store\venv\Lib\site-packages\django\template\base.py", line 1005, in <listcomp>
    return SafeString("".join([node.render_annotated(context) for node in self]))
                               ^^^^^^^^^^^^^^^^^^^^^^^^^^^^^^
  File "C:\Users\HUAWEI\OneDrive\Рабочий стол\e_store\venv\Lib\site-packages\django\template\base.py", line 966, in render_annotated
    return self.render(context)
           ^^^^^^^^^^^^^^^^^^^^
  File "C:\Users\HUAWEI\OneDrive\Рабочий стол\e_store\venv\Lib\site-packages\django\template\defaulttags.py", line 193, in render
    values = list(values)
             ^^^^^^^^^^^^
TypeError: 'Order' object is not iterable
ERROR 2024-01-25 17:51:12,675 basehttp 27904 21896 "GET /client_orders/4/ HTTP/1.1" 500 106899
INFO 2024-01-25 17:54:59,432 autoreload 27904 28960 C:\Users\HUAWEI\OneDrive\Рабочий стол\e_store\e_store\mainapp\views.py changed, reloading.
INFO 2024-01-25 17:55:00,087 autoreload 26088 29512 Watching for file changes with StatReloader
INFO 2024-01-25 17:57:39,969 autoreload 26088 29512 C:\Users\HUAWEI\OneDrive\Рабочий стол\e_store\e_store\mainapp\views.py changed, reloading.
INFO 2024-01-25 17:57:40,487 autoreload 17044 27484 Watching for file changes with StatReloader
ERROR 2024-01-25 17:57:43,263 log 17044 17060 Internal Server Error: /client_orders/4/
Traceback (most recent call last):
  File "C:\Users\HUAWEI\OneDrive\Рабочий стол\e_store\venv\Lib\site-packages\django\core\handlers\exception.py", line 55, in inner
    response = get_response(request)
               ^^^^^^^^^^^^^^^^^^^^^
  File "C:\Users\HUAWEI\OneDrive\Рабочий стол\e_store\venv\Lib\site-packages\django\core\handlers\base.py", line 204, in _get_response
    self.check_response(response, callback)
  File "C:\Users\HUAWEI\OneDrive\Рабочий стол\e_store\venv\Lib\site-packages\django\core\handlers\base.py", line 332, in check_response
    raise ValueError(
ValueError: The view mainapp.views.get_client_orders didn't return an HttpResponse object. It returned None instead.
ERROR 2024-01-25 17:57:43,264 basehttp 17044 17060 "GET /client_orders/4/ HTTP/1.1" 500 66338
INFO 2024-01-25 18:00:06,536 autoreload 19316 22880 Watching for file changes with StatReloader
ERROR 2024-01-25 18:00:08,514 log 19316 14900 Internal Server Error: /client_orders/4/
Traceback (most recent call last):
  File "C:\Users\HUAWEI\OneDrive\Рабочий стол\e_store\venv\Lib\site-packages\django\core\handlers\exception.py", line 55, in inner
    response = get_response(request)
               ^^^^^^^^^^^^^^^^^^^^^
  File "C:\Users\HUAWEI\OneDrive\Рабочий стол\e_store\venv\Lib\site-packages\django\core\handlers\base.py", line 204, in _get_response
    self.check_response(response, callback)
  File "C:\Users\HUAWEI\OneDrive\Рабочий стол\e_store\venv\Lib\site-packages\django\core\handlers\base.py", line 332, in check_response
    raise ValueError(
ValueError: The view mainapp.views.get_client_orders didn't return an HttpResponse object. It returned None instead.
ERROR 2024-01-25 18:00:08,516 basehttp 19316 14900 "GET /client_orders/4/ HTTP/1.1" 500 66338
INFO 2024-01-25 18:01:06,553 autoreload 19316 22880 C:\Users\HUAWEI\OneDrive\Рабочий стол\e_store\e_store\mainapp\views.py changed, reloading.
INFO 2024-01-25 18:01:07,137 autoreload 16548 21704 Watching for file changes with StatReloader
INFO 2024-01-25 18:01:07,433 basehttp 16548 22380 "GET /client_orders/4/ HTTP/1.1" 200 217
INFO 2024-01-25 18:11:27,182 autoreload 22280 29148 Watching for file changes with StatReloader
INFO 2024-01-25 18:11:32,439 basehttp 22280 10208 "GET /client_orders/4/ HTTP/1.1" 200 414
INFO 2024-01-25 18:12:16,121 autoreload 22280 29148 C:\Users\HUAWEI\OneDrive\Рабочий стол\e_store\e_store\mainapp\views.py changed, reloading.
INFO 2024-01-25 18:12:16,667 autoreload 21684 7004 Watching for file changes with StatReloader
INFO 2024-01-25 18:12:17,258 basehttp 21684 13584 "GET /client_orders/4/ HTTP/1.1" 200 414
INFO 2024-01-25 18:13:17,078 autoreload 21684 7004 C:\Users\HUAWEI\OneDrive\Рабочий стол\e_store\e_store\mainapp\views.py changed, reloading.
INFO 2024-01-25 18:13:17,654 autoreload 23948 3160 Watching for file changes with StatReloader
INFO 2024-01-25 18:13:52,926 autoreload 23948 3160 C:\Users\HUAWEI\OneDrive\Рабочий стол\e_store\e_store\mainapp\views.py changed, reloading.
INFO 2024-01-25 18:13:53,443 autoreload 13720 25484 Watching for file changes with StatReloader
INFO 2024-01-25 18:13:56,986 basehttp 13720 22076 "GET /client_orders/4/ HTTP/1.1" 200 414
INFO 2024-01-25 18:17:11,005 autoreload 13720 25484 C:\Users\HUAWEI\OneDrive\Рабочий стол\e_store\e_store\mainapp\views.py changed, reloading.
INFO 2024-01-25 18:17:11,573 autoreload 2256 896 Watching for file changes with StatReloader
INFO 2024-01-25 18:17:27,133 autoreload 2256 896 C:\Users\HUAWEI\OneDrive\Рабочий стол\e_store\e_store\mainapp\views.py changed, reloading.
INFO 2024-01-25 18:17:27,635 autoreload 14152 11536 Watching for file changes with StatReloader
INFO 2024-01-25 18:17:50,733 autoreload 14152 11536 C:\Users\HUAWEI\OneDrive\Рабочий стол\e_store\e_store\mainapp\views.py changed, reloading.
INFO 2024-01-25 18:17:51,251 autoreload 26260 22824 Watching for file changes with StatReloader
INFO 2024-01-25 18:19:10,690 autoreload 26260 22824 C:\Users\HUAWEI\OneDrive\Рабочий стол\e_store\e_store\mainapp\views.py changed, reloading.
INFO 2024-01-25 18:19:11,228 autoreload 12672 2624 Watching for file changes with StatReloader
ERROR 2024-01-25 18:19:21,401 log 12672 24928 Internal Server Error: /client_orders/4/
Traceback (most recent call last):
  File "C:\Users\HUAWEI\OneDrive\Рабочий стол\e_store\venv\Lib\site-packages\django\core\handlers\exception.py", line 55, in inner
    response = get_response(request)
               ^^^^^^^^^^^^^^^^^^^^^
  File "C:\Users\HUAWEI\OneDrive\Рабочий стол\e_store\venv\Lib\site-packages\django\core\handlers\base.py", line 197, in _get_response
    response = wrapped_callback(request, *callback_args, **callback_kwargs)
               ^^^^^^^^^^^^^^^^^^^^^^^^^^^^^^^^^^^^^^^^^^^^^^^^^^^^^^^^^^^^
  File "C:\Users\HUAWEI\OneDrive\Рабочий стол\e_store\e_store\mainapp\views.py", line 36, in get_client_orders
    li = [good.name for good in orders]
         ^^^^^^^^^^^^^^^^^^^^^^^^^^^^^^
  File "C:\Users\HUAWEI\OneDrive\Рабочий стол\e_store\e_store\mainapp\views.py", line 36, in <listcomp>
    li = [good.name for good in orders]
          ^^^^^^^^^
AttributeError: 'Order' object has no attribute 'name'
ERROR 2024-01-25 18:19:21,403 basehttp 12672 24928 "GET /client_orders/4/ HTTP/1.1" 500 69536
INFO 2024-01-25 18:19:52,173 autoreload 12672 2624 C:\Users\HUAWEI\OneDrive\Рабочий стол\e_store\e_store\mainapp\views.py changed, reloading.
INFO 2024-01-25 18:19:52,759 autoreload 23216 28056 Watching for file changes with StatReloader
INFO 2024-01-25 18:19:53,508 basehttp 23216 18536 "GET /client_orders/4/ HTTP/1.1" 200 414
INFO 2024-01-25 18:20:49,885 autoreload 23216 28056 C:\Users\HUAWEI\OneDrive\Рабочий стол\e_store\e_store\mainapp\views.py changed, reloading.
INFO 2024-01-25 18:20:50,410 autoreload 7864 2784 Watching for file changes with StatReloader
INFO 2024-01-25 18:21:07,267 autoreload 7864 2784 C:\Users\HUAWEI\OneDrive\Рабочий стол\e_store\e_store\mainapp\views.py changed, reloading.
INFO 2024-01-25 18:21:07,789 autoreload 17964 2096 Watching for file changes with StatReloader
INFO 2024-01-25 18:21:15,084 basehttp 17964 24868 "GET /client_orders/4/ HTTP/1.1" 200 202
INFO 2024-01-25 18:24:37,926 autoreload 17964 2096 C:\Users\HUAWEI\OneDrive\Рабочий стол\e_store\e_store\mainapp\models.py changed, reloading.
INFO 2024-01-25 18:24:38,524 autoreload 16816 22048 Watching for file changes with StatReloader
INFO 2024-01-25 18:28:52,175 autoreload 16816 22048 C:\Users\HUAWEI\OneDrive\Рабочий стол\e_store\e_store\mainapp\views.py changed, reloading.
INFO 2024-01-25 18:28:52,652 autoreload 11144 27688 Watching for file changes with StatReloader
INFO 2024-01-25 18:28:54,804 basehttp 11144 8688 "GET /client_orders/4/ HTTP/1.1" 200 240
INFO 2024-01-25 18:30:19,372 autoreload 11144 27688 C:\Users\HUAWEI\OneDrive\Рабочий стол\e_store\e_store\mainapp\models.py changed, reloading.
INFO 2024-01-25 18:30:19,927 autoreload 17256 1420 Watching for file changes with StatReloader
INFO 2024-01-25 18:31:44,259 autoreload 17256 1420 C:\Users\HUAWEI\OneDrive\Рабочий стол\e_store\e_store\mainapp\views.py changed, reloading.
INFO 2024-01-25 18:31:44,770 autoreload 17844 27136 Watching for file changes with StatReloader
INFO 2024-01-25 18:33:10,944 autoreload 17844 27136 C:\Users\HUAWEI\OneDrive\Рабочий стол\e_store\e_store\mainapp\views.py changed, reloading.
INFO 2024-01-25 18:33:11,436 autoreload 26840 24036 Watching for file changes with StatReloader
INFO 2024-01-25 18:33:37,155 autoreload 26840 24036 C:\Users\HUAWEI\OneDrive\Рабочий стол\e_store\e_store\mainapp\views.py changed, reloading.
INFO 2024-01-25 18:33:37,729 autoreload 16360 22160 Watching for file changes with StatReloader
INFO 2024-01-25 18:33:40,264 basehttp 16360 26220 "GET /client_orders/4/ HTTP/1.1" 200 255
INFO 2024-01-25 18:35:00,981 autoreload 16360 22160 C:\Users\HUAWEI\OneDrive\Рабочий стол\e_store\e_store\mainapp\views.py changed, reloading.
INFO 2024-01-25 18:35:01,503 autoreload 20896 20160 Watching for file changes with StatReloader
INFO 2024-01-25 18:35:04,070 basehttp 20896 29232 "GET /client_orders/4/ HTTP/1.1" 200 255
INFO 2024-01-25 18:35:34,883 autoreload 20896 20160 C:\Users\HUAWEI\OneDrive\Рабочий стол\e_store\e_store\mainapp\views.py changed, reloading.
INFO 2024-01-25 18:35:35,411 autoreload 24980 5800 Watching for file changes with StatReloader
INFO 2024-01-25 18:35:44,817 basehttp 24980 9524 "GET / HTTP/1.1" 200 117
INFO 2024-01-25 18:35:47,039 basehttp 24980 9524 - Broken pipe from ('127.0.0.1', 37101)
INFO 2024-01-25 18:35:53,462 basehttp 24980 20324 "GET /client_orders/4/ HTTP/1.1" 200 255
INFO 2024-01-25 18:38:18,008 autoreload 24980 5800 C:\Users\HUAWEI\OneDrive\Рабочий стол\e_store\e_store\mainapp\models.py changed, reloading.
INFO 2024-01-25 18:38:18,520 autoreload 8112 28728 Watching for file changes with StatReloader
INFO 2024-01-25 18:39:28,930 autoreload 8112 28728 C:\Users\HUAWEI\OneDrive\Рабочий стол\e_store\e_store\mainapp\models.py changed, reloading.
INFO 2024-01-25 18:39:29,444 autoreload 29156 23340 Watching for file changes with StatReloader
INFO 2024-01-25 18:40:45,567 autoreload 29156 23340 C:\Users\HUAWEI\OneDrive\Рабочий стол\e_store\e_store\mainapp\models.py changed, reloading.
INFO 2024-01-25 18:40:46,127 autoreload 4936 21564 Watching for file changes with StatReloader
INFO 2024-01-25 18:42:15,560 autoreload 4936 21564 C:\Users\HUAWEI\OneDrive\Рабочий стол\e_store\e_store\mainapp\models.py changed, reloading.
INFO 2024-01-25 18:42:16,110 autoreload 12784 26528 Watching for file changes with StatReloader
INFO 2024-01-25 18:42:25,728 autoreload 12784 26528 C:\Users\HUAWEI\OneDrive\Рабочий стол\e_store\e_store\mainapp\models.py changed, reloading.
INFO 2024-01-25 18:42:26,457 autoreload 28872 29080 Watching for file changes with StatReloader
INFO 2024-01-25 18:44:16,804 autoreload 28872 29080 C:\Users\HUAWEI\OneDrive\Рабочий стол\e_store\e_store\mainapp\views.py changed, reloading.
INFO 2024-01-25 18:44:17,335 autoreload 12200 19056 Watching for file changes with StatReloader
ERROR 2024-01-25 18:44:19,516 log 12200 26284 Internal Server Error: /client_orders/4/
Traceback (most recent call last):
  File "C:\Users\HUAWEI\OneDrive\Рабочий стол\e_store\venv\Lib\site-packages\django\core\handlers\exception.py", line 55, in inner
    response = get_response(request)
               ^^^^^^^^^^^^^^^^^^^^^
  File "C:\Users\HUAWEI\OneDrive\Рабочий стол\e_store\venv\Lib\site-packages\django\core\handlers\base.py", line 197, in _get_response
    response = wrapped_callback(request, *callback_args, **callback_kwargs)
               ^^^^^^^^^^^^^^^^^^^^^^^^^^^^^^^^^^^^^^^^^^^^^^^^^^^^^^^^^^^^
  File "C:\Users\HUAWEI\OneDrive\Рабочий стол\e_store\e_store\mainapp\views.py", line 35, in get_client_orders
    li = [order.get_goods() for order in orders]
         ^^^^^^^^^^^^^^^^^^^^^^^^^^^^^^^^^^^^^^^
  File "C:\Users\HUAWEI\OneDrive\Рабочий стол\e_store\e_store\mainapp\views.py", line 35, in <listcomp>
    li = [order.get_goods() for order in orders]
          ^^^^^^^^^^^^^^^^^
  File "C:\Users\HUAWEI\OneDrive\Рабочий стол\e_store\e_store\mainapp\models.py", line 36, in get_goods
    return [good.name for good in self.goods]
           ^^^^^^^^^^^^^^^^^^^^^^^^^^^^^^^^^^
TypeError: 'ManyRelatedManager' object is not iterable
ERROR 2024-01-25 18:44:19,520 basehttp 12200 26284 "GET /client_orders/4/ HTTP/1.1" 500 71733
INFO 2024-01-25 18:46:22,382 autoreload 12200 19056 C:\Users\HUAWEI\OneDrive\Рабочий стол\e_store\e_store\mainapp\models.py changed, reloading.
INFO 2024-01-25 18:46:23,015 autoreload 24976 29632 Watching for file changes with StatReloader
ERROR 2024-01-25 18:46:24,439 log 24976 2952 Internal Server Error: /client_orders/4/
Traceback (most recent call last):
  File "C:\Users\HUAWEI\OneDrive\Рабочий стол\e_store\venv\Lib\site-packages\django\core\handlers\exception.py", line 55, in inner
    response = get_response(request)
               ^^^^^^^^^^^^^^^^^^^^^
  File "C:\Users\HUAWEI\OneDrive\Рабочий стол\e_store\venv\Lib\site-packages\django\core\handlers\base.py", line 197, in _get_response
    response = wrapped_callback(request, *callback_args, **callback_kwargs)
               ^^^^^^^^^^^^^^^^^^^^^^^^^^^^^^^^^^^^^^^^^^^^^^^^^^^^^^^^^^^^
  File "C:\Users\HUAWEI\OneDrive\Рабочий стол\e_store\e_store\mainapp\views.py", line 35, in get_client_orders
    li = [order.get_goods() for order in orders]
         ^^^^^^^^^^^^^^^^^^^^^^^^^^^^^^^^^^^^^^^
  File "C:\Users\HUAWEI\OneDrive\Рабочий стол\e_store\e_store\mainapp\views.py", line 35, in <listcomp>
    li = [order.get_goods() for order in orders]
          ^^^^^^^^^^^^^^^^^
  File "C:\Users\HUAWEI\OneDrive\Рабочий стол\e_store\e_store\mainapp\models.py", line 36, in get_goods
    return [good for good in self.goods.name]
           ^^^^^^^^^^^^^^^^^^^^^^^^^^^^^^^^^^
TypeError: 'NoneType' object is not iterable
ERROR 2024-01-25 18:46:24,441 basehttp 24976 2952 "GET /client_orders/4/ HTTP/1.1" 500 71693
INFO 2024-01-25 18:48:13,099 autoreload 24976 29632 C:\Users\HUAWEI\OneDrive\Рабочий стол\e_store\e_store\mainapp\models.py changed, reloading.
INFO 2024-01-25 18:48:13,696 autoreload 27636 29148 Watching for file changes with StatReloader
INFO 2024-01-25 18:48:14,716 basehttp 27636 23452 "GET /client_orders/4/ HTTP/1.1" 200 255
INFO 2024-01-25 18:49:14,590 autoreload 27636 29148 C:\Users\HUAWEI\OneDrive\Рабочий стол\e_store\e_store\mainapp\views.py changed, reloading.
INFO 2024-01-25 18:49:15,094 autoreload 9848 29180 Watching for file changes with StatReloader
INFO 2024-01-25 18:49:15,904 basehttp 9848 20756 "GET /client_orders/4/ HTTP/1.1" 200 255
INFO 2024-01-25 18:49:58,507 autoreload 9848 29180 C:\Users\HUAWEI\OneDrive\Рабочий стол\e_store\e_store\mainapp\views.py changed, reloading.
INFO 2024-01-25 18:49:59,054 autoreload 16316 6176 Watching for file changes with StatReloader
INFO 2024-01-25 18:49:59,373 basehttp 16316 21496 "GET /client_orders/4/ HTTP/1.1" 200 255
INFO 2024-01-25 18:50:53,755 autoreload 16316 6176 C:\Users\HUAWEI\OneDrive\Рабочий стол\e_store\e_store\mainapp\views.py changed, reloading.
INFO 2024-01-25 18:50:54,263 autoreload 16024 28392 Watching for file changes with StatReloader
INFO 2024-01-25 18:50:57,272 basehttp 16024 27028 "GET /client_orders/4/ HTTP/1.1" 200 234
INFO 2024-01-25 18:56:47,274 basehttp 16024 23436 "GET /client_orders/4/ HTTP/1.1" 200 338
INFO 2024-01-25 18:56:49,574 basehttp 16024 23436 "GET /client_orders/4/ HTTP/1.1" 200 338
INFO 2024-01-25 18:58:06,215 autoreload 16024 28392 C:\Users\HUAWEI\OneDrive\Рабочий стол\e_store\e_store\mainapp\models.py changed, reloading.
INFO 2024-01-25 18:58:06,989 autoreload 23720 10572 Watching for file changes with StatReloader
INFO 2024-01-25 18:58:07,474 basehttp 23720 16816 "GET /client_orders/4/ HTTP/1.1" 200 338
INFO 2024-01-25 18:58:31,967 autoreload 23720 10572 C:\Users\HUAWEI\OneDrive\Рабочий стол\e_store\e_store\mainapp\models.py changed, reloading.
INFO 2024-01-25 18:58:32,517 autoreload 24092 23148 Watching for file changes with StatReloader
ERROR 2024-01-25 18:58:33,014 log 24092 21808 Internal Server Error: /client_orders/4/
Traceback (most recent call last):
  File "C:\Users\HUAWEI\OneDrive\Рабочий стол\e_store\venv\Lib\site-packages\django\core\handlers\exception.py", line 55, in inner
    response = get_response(request)
               ^^^^^^^^^^^^^^^^^^^^^
  File "C:\Users\HUAWEI\OneDrive\Рабочий стол\e_store\venv\Lib\site-packages\django\core\handlers\base.py", line 197, in _get_response
    response = wrapped_callback(request, *callback_args, **callback_kwargs)
               ^^^^^^^^^^^^^^^^^^^^^^^^^^^^^^^^^^^^^^^^^^^^^^^^^^^^^^^^^^^^
  File "C:\Users\HUAWEI\OneDrive\Рабочий стол\e_store\e_store\mainapp\views.py", line 35, in get_client_orders
    li = [order.get_goods() for order in orders]
         ^^^^^^^^^^^^^^^^^^^^^^^^^^^^^^^^^^^^^^^
  File "C:\Users\HUAWEI\OneDrive\Рабочий стол\e_store\e_store\mainapp\views.py", line 35, in <listcomp>
    li = [order.get_goods() for order in orders]
          ^^^^^^^^^^^^^^^^^
  File "C:\Users\HUAWEI\OneDrive\Рабочий стол\e_store\e_store\mainapp\models.py", line 36, in get_goods
    return [zip(good.name, good.price) for good in self.goods.all()]
           ^^^^^^^^^^^^^^^^^^^^^^^^^^^^^^^^^^^^^^^^^^^^^^^^^^^^^^^^^
  File "C:\Users\HUAWEI\OneDrive\Рабочий стол\e_store\e_store\mainapp\models.py", line 36, in <listcomp>
    return [zip(good.name, good.price) for good in self.goods.all()]
            ^^^^^^^^^^^^^^^^^^^^^^^^^^
TypeError: 'decimal.Decimal' object is not iterable
ERROR 2024-01-25 18:58:33,016 basehttp 24092 21808 "GET /client_orders/4/ HTTP/1.1" 500 74764
INFO 2024-01-25 18:59:30,855 autoreload 24092 23148 C:\Users\HUAWEI\OneDrive\Рабочий стол\e_store\e_store\mainapp\models.py changed, reloading.
INFO 2024-01-25 18:59:31,522 autoreload 14096 29272 Watching for file changes with StatReloader
INFO 2024-01-25 18:59:33,001 basehttp 14096 27952 "GET /client_orders/4/ HTTP/1.1" 200 338
INFO 2024-01-25 19:00:33,535 autoreload 14096 29272 C:\Users\HUAWEI\OneDrive\Рабочий стол\e_store\e_store\mainapp\models.py changed, reloading.
INFO 2024-01-25 19:00:34,070 autoreload 29396 28112 Watching for file changes with StatReloader
INFO 2024-01-25 19:00:34,889 basehttp 29396 26064 "GET /client_orders/4/ HTTP/1.1" 200 338
INFO 2024-01-25 19:00:57,960 autoreload 29396 28112 C:\Users\HUAWEI\OneDrive\Рабочий стол\e_store\e_store\mainapp\models.py changed, reloading.
INFO 2024-01-25 19:00:58,614 autoreload 27324 20432 Watching for file changes with StatReloader
INFO 2024-01-25 19:00:58,975 basehttp 27324 8132 "GET /client_orders/4/ HTTP/1.1" 200 338
INFO 2024-01-25 19:01:58,417 autoreload 27324 20432 C:\Users\HUAWEI\OneDrive\Рабочий стол\e_store\e_store\mainapp\views.py changed, reloading.
INFO 2024-01-25 19:01:58,885 autoreload 12148 1636 Watching for file changes with StatReloader
INFO 2024-01-25 19:02:05,448 basehttp 12148 6352 "GET /client_orders/4/ HTTP/1.1" 200 338
INFO 2024-01-25 19:02:35,301 autoreload 12148 1636 C:\Users\HUAWEI\OneDrive\Рабочий стол\e_store\e_store\mainapp\views.py changed, reloading.
INFO 2024-01-25 19:02:35,817 autoreload 17624 18100 Watching for file changes with StatReloader
ERROR 2024-01-25 19:02:36,380 log 17624 28160 Internal Server Error: /client_orders/4/
Traceback (most recent call last):
  File "C:\Users\HUAWEI\OneDrive\Рабочий стол\e_store\venv\Lib\site-packages\django\core\handlers\exception.py", line 55, in inner
    response = get_response(request)
               ^^^^^^^^^^^^^^^^^^^^^
  File "C:\Users\HUAWEI\OneDrive\Рабочий стол\e_store\venv\Lib\site-packages\django\core\handlers\base.py", line 197, in _get_response
    response = wrapped_callback(request, *callback_args, **callback_kwargs)
               ^^^^^^^^^^^^^^^^^^^^^^^^^^^^^^^^^^^^^^^^^^^^^^^^^^^^^^^^^^^^
  File "C:\Users\HUAWEI\OneDrive\Рабочий стол\e_store\e_store\mainapp\views.py", line 37, in get_client_orders
    print(**li)
TypeError: print() argument after ** must be a mapping, not list
ERROR 2024-01-25 19:02:36,382 basehttp 17624 28160 "GET /client_orders/4/ HTTP/1.1" 500 65499
INFO 2024-01-25 19:04:51,433 autoreload 17624 18100 C:\Users\HUAWEI\OneDrive\Рабочий стол\e_store\e_store\mainapp\views.py changed, reloading.
INFO 2024-01-25 19:04:51,971 autoreload 19040 28300 Watching for file changes with StatReloader
INFO 2024-01-25 19:06:18,865 autoreload 19040 28300 C:\Users\HUAWEI\OneDrive\Рабочий стол\e_store\e_store\mainapp\views.py changed, reloading.
INFO 2024-01-25 19:06:19,516 autoreload 11664 23540 Watching for file changes with StatReloader
INFO 2024-01-25 19:06:48,674 autoreload 11664 23540 C:\Users\HUAWEI\OneDrive\Рабочий стол\e_store\e_store\mainapp\views.py changed, reloading.
INFO 2024-01-25 19:06:49,235 autoreload 25620 3744 Watching for file changes with StatReloader
INFO 2024-01-25 19:07:18,044 autoreload 25620 3744 C:\Users\HUAWEI\OneDrive\Рабочий стол\e_store\e_store\mainapp\views.py changed, reloading.
INFO 2024-01-25 19:07:18,626 autoreload 16224 19532 Watching for file changes with StatReloader
INFO 2024-01-25 19:07:24,355 basehttp 16224 26604 "GET / HTTP/1.1" 200 117
INFO 2024-01-25 19:07:29,185 basehttp 16224 26604 "GET /client_orders/4/ HTTP/1.1" 200 338
INFO 2024-01-25 19:07:59,359 autoreload 16224 19532 C:\Users\HUAWEI\OneDrive\Рабочий стол\e_store\e_store\mainapp\views.py changed, reloading.
INFO 2024-01-25 19:07:59,879 autoreload 15864 28152 Watching for file changes with StatReloader
INFO 2024-01-25 19:08:00,514 basehttp 15864 22108 "GET /client_orders/4/ HTTP/1.1" 200 338
INFO 2024-01-25 19:10:41,586 basehttp 15864 22004 "GET /client_orders/4/ HTTP/1.1" 200 246
INFO 2024-01-25 19:11:59,206 basehttp 15864 22004 "GET /client_orders/4/ HTTP/1.1" 200 451
INFO 2024-01-25 19:12:59,262 basehttp 15864 22004 "GET /client_orders/4/ HTTP/1.1" 200 550
INFO 2024-01-25 19:13:35,784 autoreload 15864 28152 C:\Users\HUAWEI\OneDrive\Рабочий стол\e_store\e_store\mainapp\views.py changed, reloading.
INFO 2024-01-25 19:13:36,291 autoreload 22956 6044 Watching for file changes with StatReloader
INFO 2024-01-25 19:13:37,992 basehttp 22956 25728 "GET /client_orders/4/ HTTP/1.1" 200 639
INFO 2024-01-25 19:14:09,706 basehttp 22956 25728 "GET /client_orders/4/ HTTP/1.1" 200 499
INFO 2024-01-25 19:14:38,092 basehttp 22956 25728 "GET /client_orders/4/ HTTP/1.1" 200 643
INFO 2024-01-25 19:16:25,783 autoreload 22956 6044 C:\Users\HUAWEI\OneDrive\Рабочий стол\e_store\e_store\mainapp\views.py changed, reloading.
INFO 2024-01-25 19:16:26,257 autoreload 1132 3060 Watching for file changes with StatReloader
INFO 2024-01-25 19:17:52,500 autoreload 1132 3060 C:\Users\HUAWEI\OneDrive\Рабочий стол\e_store\e_store\mainapp\views.py changed, reloading.
INFO 2024-01-25 19:17:53,023 autoreload 10004 24804 Watching for file changes with StatReloader
INFO 2024-01-25 19:18:36,441 basehttp 10004 21028 "GET /orders/1 HTTP/1.1" 301 0
ERROR 2024-01-25 19:18:36,505 log 10004 28812 Internal Server Error: /orders/1/
Traceback (most recent call last):
  File "C:\Users\HUAWEI\OneDrive\Рабочий стол\e_store\venv\Lib\site-packages\django\core\handlers\exception.py", line 55, in inner
    response = get_response(request)
               ^^^^^^^^^^^^^^^^^^^^^
  File "C:\Users\HUAWEI\OneDrive\Рабочий стол\e_store\venv\Lib\site-packages\django\core\handlers\base.py", line 197, in _get_response
    response = wrapped_callback(request, *callback_args, **callback_kwargs)
               ^^^^^^^^^^^^^^^^^^^^^^^^^^^^^^^^^^^^^^^^^^^^^^^^^^^^^^^^^^^^
  File "C:\Users\HUAWEI\OneDrive\Рабочий стол\e_store\e_store\mainapp\views.py", line 25, in get_orders
    return render(request, 'mainapp/sorted_orders.html', {'orders': orders})
           ^^^^^^^^^^^^^^^^^^^^^^^^^^^^^^^^^^^^^^^^^^^^^^^^^^^^^^^^^^^^^^^^^
  File "C:\Users\HUAWEI\OneDrive\Рабочий стол\e_store\venv\Lib\site-packages\django\shortcuts.py", line 24, in render
    content = loader.render_to_string(template_name, context, request, using=using)
              ^^^^^^^^^^^^^^^^^^^^^^^^^^^^^^^^^^^^^^^^^^^^^^^^^^^^^^^^^^^^^^^^^^^^^
  File "C:\Users\HUAWEI\OneDrive\Рабочий стол\e_store\venv\Lib\site-packages\django\template\loader.py", line 61, in render_to_string
    template = get_template(template_name, using=using)
               ^^^^^^^^^^^^^^^^^^^^^^^^^^^^^^^^^^^^^^^^
  File "C:\Users\HUAWEI\OneDrive\Рабочий стол\e_store\venv\Lib\site-packages\django\template\loader.py", line 19, in get_template
    raise TemplateDoesNotExist(template_name, chain=chain)
django.template.exceptions.TemplateDoesNotExist: mainapp/sorted_orders.html
ERROR 2024-01-25 19:18:36,509 basehttp 10004 28812 "GET /orders/1/ HTTP/1.1" 500 81709
INFO 2024-01-25 19:19:51,470 basehttp 10004 28812 "GET /orders/1/ HTTP/1.1" 200 264
INFO 2024-01-25 19:20:08,932 autoreload 10004 24804 C:\Users\HUAWEI\OneDrive\Рабочий стол\e_store\e_store\mainapp\models.py changed, reloading.
INFO 2024-01-25 19:20:09,534 autoreload 14688 11436 Watching for file changes with StatReloader
INFO 2024-01-25 19:20:10,272 basehttp 14688 18104 "GET /orders/1/ HTTP/1.1" 200 264
INFO 2024-01-25 19:20:55,209 basehttp 14688 18104 "GET /orders/1/ HTTP/1.1" 200 233
INFO 2024-01-27 18:44:03,867 autoreload 10508 29356 Watching for file changes with StatReloader
INFO 2024-01-27 18:58:20,797 autoreload 10508 29356 C:\Users\HUAWEI\OneDrive\Рабочий стол\e_store\e_store\mainapp\views.py changed, reloading.
INFO 2024-01-27 18:58:21,459 autoreload 8208 2732 Watching for file changes with StatReloader
INFO 2024-01-28 13:10:16,174 autoreload 3972 19160 Watching for file changes with StatReloader
INFO 2024-01-28 13:10:17,671 basehttp 3972 21228 "GET / HTTP/1.1" 200 117
INFO 2024-01-28 13:10:23,686 basehttp 3972 19172 "GET /add_good HTTP/1.1" 301 0
ERROR 2024-01-28 13:10:23,745 log 3972 12024 Internal Server Error: /add_good/
Traceback (most recent call last):
  File "C:\Users\HUAWEI\OneDrive\Рабочий стол\e_store\venv\Lib\site-packages\django\core\handlers\exception.py", line 55, in inner
    response = get_response(request)
               ^^^^^^^^^^^^^^^^^^^^^
  File "C:\Users\HUAWEI\OneDrive\Рабочий стол\e_store\venv\Lib\site-packages\django\core\handlers\base.py", line 204, in _get_response
    self.check_response(response, callback)
  File "C:\Users\HUAWEI\OneDrive\Рабочий стол\e_store\venv\Lib\site-packages\django\core\handlers\base.py", line 332, in check_response
    raise ValueError(
ValueError: The view mainapp.views.create_good didn't return an HttpResponse object. It returned None instead.
ERROR 2024-01-28 13:10:23,747 basehttp 3972 12024 "GET /add_good/ HTTP/1.1" 500 66148
INFO 2024-01-28 13:11:47,005 autoreload 3972 19160 C:\Users\HUAWEI\OneDrive\Рабочий стол\e_store\e_store\mainapp\views.py changed, reloading.
INFO 2024-01-28 13:11:47,675 autoreload 26968 24940 Watching for file changes with StatReloader
ERROR 2024-01-28 13:11:47,915 log 26968 15592 Internal Server Error: /add_good/
Traceback (most recent call last):
  File "C:\Users\HUAWEI\OneDrive\Рабочий стол\e_store\venv\Lib\site-packages\django\core\handlers\exception.py", line 55, in inner
    response = get_response(request)
               ^^^^^^^^^^^^^^^^^^^^^
  File "C:\Users\HUAWEI\OneDrive\Рабочий стол\e_store\venv\Lib\site-packages\django\core\handlers\base.py", line 204, in _get_response
    self.check_response(response, callback)
  File "C:\Users\HUAWEI\OneDrive\Рабочий стол\e_store\venv\Lib\site-packages\django\core\handlers\base.py", line 332, in check_response
    raise ValueError(
ValueError: The view mainapp.views.create_good didn't return an HttpResponse object. It returned None instead.
ERROR 2024-01-28 13:11:47,916 basehttp 26968 15592 "GET /add_good/ HTTP/1.1" 500 66285
ERROR 2024-01-28 13:13:45,969 log 26968 8892 Internal Server Error: /add_good/
Traceback (most recent call last):
  File "C:\Users\HUAWEI\OneDrive\Рабочий стол\e_store\venv\Lib\site-packages\django\core\handlers\exception.py", line 55, in inner
    response = get_response(request)
               ^^^^^^^^^^^^^^^^^^^^^
  File "C:\Users\HUAWEI\OneDrive\Рабочий стол\e_store\venv\Lib\site-packages\django\core\handlers\base.py", line 204, in _get_response
    self.check_response(response, callback)
  File "C:\Users\HUAWEI\OneDrive\Рабочий стол\e_store\venv\Lib\site-packages\django\core\handlers\base.py", line 332, in check_response
    raise ValueError(
ValueError: The view mainapp.views.create_good didn't return an HttpResponse object. It returned None instead.
ERROR 2024-01-28 13:13:45,970 basehttp 26968 8892 "GET /add_good/ HTTP/1.1" 500 66285
INFO 2024-01-28 13:14:22,741 autoreload 26968 24940 C:\Users\HUAWEI\OneDrive\Рабочий стол\e_store\e_store\mainapp\forms.py changed, reloading.
INFO 2024-01-28 13:14:23,258 autoreload 16488 8656 Watching for file changes with StatReloader
INFO 2024-01-28 13:16:39,740 autoreload 16488 8656 C:\Users\HUAWEI\OneDrive\Рабочий стол\e_store\e_store\mainapp\views.py changed, reloading.
INFO 2024-01-28 13:16:40,235 autoreload 27724 11268 Watching for file changes with StatReloader
INFO 2024-01-28 13:17:01,332 autoreload 27724 11268 C:\Users\HUAWEI\OneDrive\Рабочий стол\e_store\e_store\mainapp\views.py changed, reloading.
INFO 2024-01-28 13:17:02,040 autoreload 21144 5412 Watching for file changes with StatReloader
ERROR 2024-01-28 13:17:04,697 log 21144 21016 Internal Server Error: /add_good/
Traceback (most recent call last):
  File "C:\Users\HUAWEI\OneDrive\Рабочий стол\e_store\venv\Lib\site-packages\django\core\handlers\exception.py", line 55, in inner
    response = get_response(request)
               ^^^^^^^^^^^^^^^^^^^^^
  File "C:\Users\HUAWEI\OneDrive\Рабочий стол\e_store\venv\Lib\site-packages\django\core\handlers\base.py", line 204, in _get_response
    self.check_response(response, callback)
  File "C:\Users\HUAWEI\OneDrive\Рабочий стол\e_store\venv\Lib\site-packages\django\core\handlers\base.py", line 332, in check_response
    raise ValueError(
ValueError: The view mainapp.views.create_good didn't return an HttpResponse object. It returned None instead.
ERROR 2024-01-28 13:17:04,698 basehttp 21144 21016 "GET /add_good/ HTTP/1.1" 500 66285
ERROR 2024-01-28 13:20:55,283 log 21144 15716 Internal Server Error: /add_good/
Traceback (most recent call last):
  File "C:\Users\HUAWEI\OneDrive\Рабочий стол\e_store\venv\Lib\site-packages\django\core\handlers\exception.py", line 55, in inner
    response = get_response(request)
               ^^^^^^^^^^^^^^^^^^^^^
  File "C:\Users\HUAWEI\OneDrive\Рабочий стол\e_store\venv\Lib\site-packages\django\core\handlers\base.py", line 204, in _get_response
    self.check_response(response, callback)
  File "C:\Users\HUAWEI\OneDrive\Рабочий стол\e_store\venv\Lib\site-packages\django\core\handlers\base.py", line 332, in check_response
    raise ValueError(
ValueError: The view mainapp.views.create_good didn't return an HttpResponse object. It returned None instead.
ERROR 2024-01-28 13:20:55,284 basehttp 21144 15716 "GET /add_good/ HTTP/1.1" 500 66285
INFO 2024-01-28 13:22:04,037 autoreload 21144 5412 C:\Users\HUAWEI\OneDrive\Рабочий стол\e_store\e_store\mainapp\views.py changed, reloading.
INFO 2024-01-28 13:22:04,582 autoreload 27416 29580 Watching for file changes with StatReloader
ERROR 2024-01-28 13:22:05,777 log 27416 10312 Internal Server Error: /add_good/
Traceback (most recent call last):
  File "C:\Users\HUAWEI\OneDrive\Рабочий стол\e_store\venv\Lib\site-packages\django\core\handlers\exception.py", line 55, in inner
    response = get_response(request)
               ^^^^^^^^^^^^^^^^^^^^^
  File "C:\Users\HUAWEI\OneDrive\Рабочий стол\e_store\venv\Lib\site-packages\django\core\handlers\base.py", line 204, in _get_response
    self.check_response(response, callback)
  File "C:\Users\HUAWEI\OneDrive\Рабочий стол\e_store\venv\Lib\site-packages\django\core\handlers\base.py", line 332, in check_response
    raise ValueError(
ValueError: The view mainapp.views.create_good didn't return an HttpResponse object. It returned None instead.
ERROR 2024-01-28 13:22:05,778 basehttp 27416 10312 "GET /add_good/ HTTP/1.1" 500 66285
ERROR 2024-01-28 13:23:41,678 log 27416 1784 Internal Server Error: /add_good/
Traceback (most recent call last):
  File "C:\Users\HUAWEI\OneDrive\Рабочий стол\e_store\venv\Lib\site-packages\django\core\handlers\exception.py", line 55, in inner
    response = get_response(request)
               ^^^^^^^^^^^^^^^^^^^^^
  File "C:\Users\HUAWEI\OneDrive\Рабочий стол\e_store\venv\Lib\site-packages\django\core\handlers\base.py", line 204, in _get_response
    self.check_response(response, callback)
  File "C:\Users\HUAWEI\OneDrive\Рабочий стол\e_store\venv\Lib\site-packages\django\core\handlers\base.py", line 332, in check_response
    raise ValueError(
ValueError: The view mainapp.views.create_good didn't return an HttpResponse object. It returned None instead.
ERROR 2024-01-28 13:23:41,679 basehttp 27416 1784 "GET /add_good/ HTTP/1.1" 500 66285
INFO 2024-01-28 13:25:20,165 autoreload 27416 29580 C:\Users\HUAWEI\OneDrive\Рабочий стол\e_store\e_store\mainapp\views.py changed, reloading.
INFO 2024-01-28 13:25:20,711 autoreload 24708 25464 Watching for file changes with StatReloader
INFO 2024-01-28 13:25:25,281 autoreload 24708 25464 C:\Users\HUAWEI\OneDrive\Рабочий стол\e_store\e_store\mainapp\views.py changed, reloading.
INFO 2024-01-28 13:25:25,765 autoreload 23700 10004 Watching for file changes with StatReloader
ERROR 2024-01-28 13:25:26,440 log 23700 22392 Internal Server Error: /add_good/
Traceback (most recent call last):
  File "C:\Users\HUAWEI\OneDrive\Рабочий стол\e_store\venv\Lib\site-packages\django\template\backends\django.py", line 61, in render
    return self.template.render(context)
           ^^^^^^^^^^^^^^^^^^^^^^^^^^^^^
  File "C:\Users\HUAWEI\OneDrive\Рабочий стол\e_store\venv\Lib\site-packages\django\template\base.py", line 175, in render
    return self._render(context)
           ^^^^^^^^^^^^^^^^^^^^^
  File "C:\Users\HUAWEI\OneDrive\Рабочий стол\e_store\venv\Lib\site-packages\django\template\base.py", line 167, in _render
    return self.nodelist.render(context)
           ^^^^^^^^^^^^^^^^^^^^^^^^^^^^^
  File "C:\Users\HUAWEI\OneDrive\Рабочий стол\e_store\venv\Lib\site-packages\django\template\base.py", line 1005, in render
    return SafeString("".join([node.render_annotated(context) for node in self]))
                              ^^^^^^^^^^^^^^^^^^^^^^^^^^^^^^^^^^^^^^^^^^^^^^^^^
  File "C:\Users\HUAWEI\OneDrive\Рабочий стол\e_store\venv\Lib\site-packages\django\template\base.py", line 1005, in <listcomp>
    return SafeString("".join([node.render_annotated(context) for node in self]))
                               ^^^^^^^^^^^^^^^^^^^^^^^^^^^^^^
  File "C:\Users\HUAWEI\OneDrive\Рабочий стол\e_store\venv\Lib\site-packages\django\template\base.py", line 966, in render_annotated
    return self.render(context)
           ^^^^^^^^^^^^^^^^^^^^
  File "C:\Users\HUAWEI\OneDrive\Рабочий стол\e_store\venv\Lib\site-packages\django\template\loader_tags.py", line 132, in render
    compiled_parent = self.get_parent(context)
                      ^^^^^^^^^^^^^^^^^^^^^^^^
  File "C:\Users\HUAWEI\OneDrive\Рабочий стол\e_store\venv\Lib\site-packages\django\template\loader_tags.py", line 129, in get_parent
    return self.find_template(parent, context)
           ^^^^^^^^^^^^^^^^^^^^^^^^^^^^^^^^^^^
  File "C:\Users\HUAWEI\OneDrive\Рабочий стол\e_store\venv\Lib\site-packages\django\template\loader_tags.py", line 107, in find_template
    template, origin = context.template.engine.find_template(
                       ^^^^^^^^^^^^^^^^^^^^^^^^^^^^^^^^^^^^^^
  File "C:\Users\HUAWEI\OneDrive\Рабочий стол\e_store\venv\Lib\site-packages\django\template\engine.py", line 161, in find_template
    raise TemplateDoesNotExist(name, tried=tried)
django.template.exceptions.TemplateDoesNotExist: base.html

The above exception was the direct cause of the following exception:

Traceback (most recent call last):
  File "C:\Users\HUAWEI\OneDrive\Рабочий стол\e_store\venv\Lib\site-packages\django\core\handlers\exception.py", line 55, in inner
    response = get_response(request)
               ^^^^^^^^^^^^^^^^^^^^^
  File "C:\Users\HUAWEI\OneDrive\Рабочий стол\e_store\venv\Lib\site-packages\django\core\handlers\base.py", line 197, in _get_response
    response = wrapped_callback(request, *callback_args, **callback_kwargs)
               ^^^^^^^^^^^^^^^^^^^^^^^^^^^^^^^^^^^^^^^^^^^^^^^^^^^^^^^^^^^^
  File "C:\Users\HUAWEI\OneDrive\Рабочий стол\e_store\e_store\mainapp\views.py", line 52, in create_good
    return render(request, 'mainapp/good_form.html', {'form': form})
           ^^^^^^^^^^^^^^^^^^^^^^^^^^^^^^^^^^^^^^^^^^^^^^^^^^^^^^^^^
  File "C:\Users\HUAWEI\OneDrive\Рабочий стол\e_store\venv\Lib\site-packages\django\shortcuts.py", line 24, in render
    content = loader.render_to_string(template_name, context, request, using=using)
              ^^^^^^^^^^^^^^^^^^^^^^^^^^^^^^^^^^^^^^^^^^^^^^^^^^^^^^^^^^^^^^^^^^^^^
  File "C:\Users\HUAWEI\OneDrive\Рабочий стол\e_store\venv\Lib\site-packages\django\template\loader.py", line 62, in render_to_string
    return template.render(context, request)
           ^^^^^^^^^^^^^^^^^^^^^^^^^^^^^^^^^
  File "C:\Users\HUAWEI\OneDrive\Рабочий стол\e_store\venv\Lib\site-packages\django\template\backends\django.py", line 63, in render
    reraise(exc, self.backend)
  File "C:\Users\HUAWEI\OneDrive\Рабочий стол\e_store\venv\Lib\site-packages\django\template\backends\django.py", line 84, in reraise
    raise new from exc
django.template.exceptions.TemplateDoesNotExist: base.html
ERROR 2024-01-28 13:25:26,444 basehttp 23700 22392 "GET /add_good/ HTTP/1.1" 500 131660
ERROR 2024-01-28 13:33:25,828 log 23700 21076 Internal Server Error: /add_good/
Traceback (most recent call last):
  File "C:\Users\HUAWEI\OneDrive\Рабочий стол\e_store\venv\Lib\site-packages\django\template\backends\django.py", line 61, in render
    return self.template.render(context)
           ^^^^^^^^^^^^^^^^^^^^^^^^^^^^^
  File "C:\Users\HUAWEI\OneDrive\Рабочий стол\e_store\venv\Lib\site-packages\django\template\base.py", line 175, in render
    return self._render(context)
           ^^^^^^^^^^^^^^^^^^^^^
  File "C:\Users\HUAWEI\OneDrive\Рабочий стол\e_store\venv\Lib\site-packages\django\template\base.py", line 167, in _render
    return self.nodelist.render(context)
           ^^^^^^^^^^^^^^^^^^^^^^^^^^^^^
  File "C:\Users\HUAWEI\OneDrive\Рабочий стол\e_store\venv\Lib\site-packages\django\template\base.py", line 1005, in render
    return SafeString("".join([node.render_annotated(context) for node in self]))
                              ^^^^^^^^^^^^^^^^^^^^^^^^^^^^^^^^^^^^^^^^^^^^^^^^^
  File "C:\Users\HUAWEI\OneDrive\Рабочий стол\e_store\venv\Lib\site-packages\django\template\base.py", line 1005, in <listcomp>
    return SafeString("".join([node.render_annotated(context) for node in self]))
                               ^^^^^^^^^^^^^^^^^^^^^^^^^^^^^^
  File "C:\Users\HUAWEI\OneDrive\Рабочий стол\e_store\venv\Lib\site-packages\django\template\base.py", line 966, in render_annotated
    return self.render(context)
           ^^^^^^^^^^^^^^^^^^^^
  File "C:\Users\HUAWEI\OneDrive\Рабочий стол\e_store\venv\Lib\site-packages\django\template\loader_tags.py", line 132, in render
    compiled_parent = self.get_parent(context)
                      ^^^^^^^^^^^^^^^^^^^^^^^^
  File "C:\Users\HUAWEI\OneDrive\Рабочий стол\e_store\venv\Lib\site-packages\django\template\loader_tags.py", line 129, in get_parent
    return self.find_template(parent, context)
           ^^^^^^^^^^^^^^^^^^^^^^^^^^^^^^^^^^^
  File "C:\Users\HUAWEI\OneDrive\Рабочий стол\e_store\venv\Lib\site-packages\django\template\loader_tags.py", line 107, in find_template
    template, origin = context.template.engine.find_template(
                       ^^^^^^^^^^^^^^^^^^^^^^^^^^^^^^^^^^^^^^
  File "C:\Users\HUAWEI\OneDrive\Рабочий стол\e_store\venv\Lib\site-packages\django\template\engine.py", line 161, in find_template
    raise TemplateDoesNotExist(name, tried=tried)
django.template.exceptions.TemplateDoesNotExist: base.html

The above exception was the direct cause of the following exception:

Traceback (most recent call last):
  File "C:\Users\HUAWEI\OneDrive\Рабочий стол\e_store\venv\Lib\site-packages\django\core\handlers\exception.py", line 55, in inner
    response = get_response(request)
               ^^^^^^^^^^^^^^^^^^^^^
  File "C:\Users\HUAWEI\OneDrive\Рабочий стол\e_store\venv\Lib\site-packages\django\core\handlers\base.py", line 197, in _get_response
    response = wrapped_callback(request, *callback_args, **callback_kwargs)
               ^^^^^^^^^^^^^^^^^^^^^^^^^^^^^^^^^^^^^^^^^^^^^^^^^^^^^^^^^^^^
  File "C:\Users\HUAWEI\OneDrive\Рабочий стол\e_store\e_store\mainapp\views.py", line 52, in create_good
    return render(request, 'mainapp/good_form.html', {'form': form})
           ^^^^^^^^^^^^^^^^^^^^^^^^^^^^^^^^^^^^^^^^^^^^^^^^^^^^^^^^^
  File "C:\Users\HUAWEI\OneDrive\Рабочий стол\e_store\venv\Lib\site-packages\django\shortcuts.py", line 24, in render
    content = loader.render_to_string(template_name, context, request, using=using)
              ^^^^^^^^^^^^^^^^^^^^^^^^^^^^^^^^^^^^^^^^^^^^^^^^^^^^^^^^^^^^^^^^^^^^^
  File "C:\Users\HUAWEI\OneDrive\Рабочий стол\e_store\venv\Lib\site-packages\django\template\loader.py", line 62, in render_to_string
    return template.render(context, request)
           ^^^^^^^^^^^^^^^^^^^^^^^^^^^^^^^^^
  File "C:\Users\HUAWEI\OneDrive\Рабочий стол\e_store\venv\Lib\site-packages\django\template\backends\django.py", line 63, in render
    reraise(exc, self.backend)
  File "C:\Users\HUAWEI\OneDrive\Рабочий стол\e_store\venv\Lib\site-packages\django\template\backends\django.py", line 84, in reraise
    raise new from exc
django.template.exceptions.TemplateDoesNotExist: base.html
ERROR 2024-01-28 13:33:25,830 basehttp 23700 21076 "GET /add_good/ HTTP/1.1" 500 131660
ERROR 2024-01-28 13:33:57,428 log 23700 21076 Internal Server Error: /add_good/
Traceback (most recent call last):
  File "C:\Users\HUAWEI\OneDrive\Рабочий стол\e_store\venv\Lib\site-packages\django\template\backends\django.py", line 61, in render
    return self.template.render(context)
           ^^^^^^^^^^^^^^^^^^^^^^^^^^^^^
  File "C:\Users\HUAWEI\OneDrive\Рабочий стол\e_store\venv\Lib\site-packages\django\template\base.py", line 175, in render
    return self._render(context)
           ^^^^^^^^^^^^^^^^^^^^^
  File "C:\Users\HUAWEI\OneDrive\Рабочий стол\e_store\venv\Lib\site-packages\django\template\base.py", line 167, in _render
    return self.nodelist.render(context)
           ^^^^^^^^^^^^^^^^^^^^^^^^^^^^^
  File "C:\Users\HUAWEI\OneDrive\Рабочий стол\e_store\venv\Lib\site-packages\django\template\base.py", line 1005, in render
    return SafeString("".join([node.render_annotated(context) for node in self]))
                              ^^^^^^^^^^^^^^^^^^^^^^^^^^^^^^^^^^^^^^^^^^^^^^^^^
  File "C:\Users\HUAWEI\OneDrive\Рабочий стол\e_store\venv\Lib\site-packages\django\template\base.py", line 1005, in <listcomp>
    return SafeString("".join([node.render_annotated(context) for node in self]))
                               ^^^^^^^^^^^^^^^^^^^^^^^^^^^^^^
  File "C:\Users\HUAWEI\OneDrive\Рабочий стол\e_store\venv\Lib\site-packages\django\template\base.py", line 966, in render_annotated
    return self.render(context)
           ^^^^^^^^^^^^^^^^^^^^
  File "C:\Users\HUAWEI\OneDrive\Рабочий стол\e_store\venv\Lib\site-packages\django\template\loader_tags.py", line 132, in render
    compiled_parent = self.get_parent(context)
                      ^^^^^^^^^^^^^^^^^^^^^^^^
  File "C:\Users\HUAWEI\OneDrive\Рабочий стол\e_store\venv\Lib\site-packages\django\template\loader_tags.py", line 129, in get_parent
    return self.find_template(parent, context)
           ^^^^^^^^^^^^^^^^^^^^^^^^^^^^^^^^^^^
  File "C:\Users\HUAWEI\OneDrive\Рабочий стол\e_store\venv\Lib\site-packages\django\template\loader_tags.py", line 107, in find_template
    template, origin = context.template.engine.find_template(
                       ^^^^^^^^^^^^^^^^^^^^^^^^^^^^^^^^^^^^^^
  File "C:\Users\HUAWEI\OneDrive\Рабочий стол\e_store\venv\Lib\site-packages\django\template\engine.py", line 161, in find_template
    raise TemplateDoesNotExist(name, tried=tried)
django.template.exceptions.TemplateDoesNotExist: base.html

The above exception was the direct cause of the following exception:

Traceback (most recent call last):
  File "C:\Users\HUAWEI\OneDrive\Рабочий стол\e_store\venv\Lib\site-packages\django\core\handlers\exception.py", line 55, in inner
    response = get_response(request)
               ^^^^^^^^^^^^^^^^^^^^^
  File "C:\Users\HUAWEI\OneDrive\Рабочий стол\e_store\venv\Lib\site-packages\django\core\handlers\base.py", line 197, in _get_response
    response = wrapped_callback(request, *callback_args, **callback_kwargs)
               ^^^^^^^^^^^^^^^^^^^^^^^^^^^^^^^^^^^^^^^^^^^^^^^^^^^^^^^^^^^^
  File "C:\Users\HUAWEI\OneDrive\Рабочий стол\e_store\e_store\mainapp\views.py", line 52, in create_good
    return render(request, 'mainapp/good_form.html', {'form': form})
           ^^^^^^^^^^^^^^^^^^^^^^^^^^^^^^^^^^^^^^^^^^^^^^^^^^^^^^^^^
  File "C:\Users\HUAWEI\OneDrive\Рабочий стол\e_store\venv\Lib\site-packages\django\shortcuts.py", line 24, in render
    content = loader.render_to_string(template_name, context, request, using=using)
              ^^^^^^^^^^^^^^^^^^^^^^^^^^^^^^^^^^^^^^^^^^^^^^^^^^^^^^^^^^^^^^^^^^^^^
  File "C:\Users\HUAWEI\OneDrive\Рабочий стол\e_store\venv\Lib\site-packages\django\template\loader.py", line 62, in render_to_string
    return template.render(context, request)
           ^^^^^^^^^^^^^^^^^^^^^^^^^^^^^^^^^
  File "C:\Users\HUAWEI\OneDrive\Рабочий стол\e_store\venv\Lib\site-packages\django\template\backends\django.py", line 63, in render
    reraise(exc, self.backend)
  File "C:\Users\HUAWEI\OneDrive\Рабочий стол\e_store\venv\Lib\site-packages\django\template\backends\django.py", line 84, in reraise
    raise new from exc
django.template.exceptions.TemplateDoesNotExist: base.html
ERROR 2024-01-28 13:33:57,430 basehttp 23700 21076 "GET /add_good/ HTTP/1.1" 500 131660
INFO 2024-01-28 13:36:43,386 autoreload 26968 16316 Watching for file changes with StatReloader
INFO 2024-01-28 13:36:51,527 basehttp 26968 13704 "GET / HTTP/1.1" 200 117
ERROR 2024-01-28 13:37:06,690 log 26968 13704 Internal Server Error: /add_good/
Traceback (most recent call last):
  File "C:\Users\HUAWEI\OneDrive\Рабочий стол\e_store\venv\Lib\site-packages\django\template\backends\django.py", line 61, in render
    return self.template.render(context)
           ^^^^^^^^^^^^^^^^^^^^^^^^^^^^^
  File "C:\Users\HUAWEI\OneDrive\Рабочий стол\e_store\venv\Lib\site-packages\django\template\base.py", line 175, in render
    return self._render(context)
           ^^^^^^^^^^^^^^^^^^^^^
  File "C:\Users\HUAWEI\OneDrive\Рабочий стол\e_store\venv\Lib\site-packages\django\template\base.py", line 167, in _render
    return self.nodelist.render(context)
           ^^^^^^^^^^^^^^^^^^^^^^^^^^^^^
  File "C:\Users\HUAWEI\OneDrive\Рабочий стол\e_store\venv\Lib\site-packages\django\template\base.py", line 1005, in render
    return SafeString("".join([node.render_annotated(context) for node in self]))
                              ^^^^^^^^^^^^^^^^^^^^^^^^^^^^^^^^^^^^^^^^^^^^^^^^^
  File "C:\Users\HUAWEI\OneDrive\Рабочий стол\e_store\venv\Lib\site-packages\django\template\base.py", line 1005, in <listcomp>
    return SafeString("".join([node.render_annotated(context) for node in self]))
                               ^^^^^^^^^^^^^^^^^^^^^^^^^^^^^^
  File "C:\Users\HUAWEI\OneDrive\Рабочий стол\e_store\venv\Lib\site-packages\django\template\base.py", line 966, in render_annotated
    return self.render(context)
           ^^^^^^^^^^^^^^^^^^^^
  File "C:\Users\HUAWEI\OneDrive\Рабочий стол\e_store\venv\Lib\site-packages\django\template\loader_tags.py", line 132, in render
    compiled_parent = self.get_parent(context)
                      ^^^^^^^^^^^^^^^^^^^^^^^^
  File "C:\Users\HUAWEI\OneDrive\Рабочий стол\e_store\venv\Lib\site-packages\django\template\loader_tags.py", line 129, in get_parent
    return self.find_template(parent, context)
           ^^^^^^^^^^^^^^^^^^^^^^^^^^^^^^^^^^^
  File "C:\Users\HUAWEI\OneDrive\Рабочий стол\e_store\venv\Lib\site-packages\django\template\loader_tags.py", line 107, in find_template
    template, origin = context.template.engine.find_template(
                       ^^^^^^^^^^^^^^^^^^^^^^^^^^^^^^^^^^^^^^
  File "C:\Users\HUAWEI\OneDrive\Рабочий стол\e_store\venv\Lib\site-packages\django\template\engine.py", line 161, in find_template
    raise TemplateDoesNotExist(name, tried=tried)
django.template.exceptions.TemplateDoesNotExist: base.html

The above exception was the direct cause of the following exception:

Traceback (most recent call last):
  File "C:\Users\HUAWEI\OneDrive\Рабочий стол\e_store\venv\Lib\site-packages\django\core\handlers\exception.py", line 55, in inner
    response = get_response(request)
               ^^^^^^^^^^^^^^^^^^^^^
  File "C:\Users\HUAWEI\OneDrive\Рабочий стол\e_store\venv\Lib\site-packages\django\core\handlers\base.py", line 197, in _get_response
    response = wrapped_callback(request, *callback_args, **callback_kwargs)
               ^^^^^^^^^^^^^^^^^^^^^^^^^^^^^^^^^^^^^^^^^^^^^^^^^^^^^^^^^^^^
  File "C:\Users\HUAWEI\OneDrive\Рабочий стол\e_store\e_store\mainapp\views.py", line 52, in create_good
    return render(request, 'mainapp/good_form.html', {'form': form})
           ^^^^^^^^^^^^^^^^^^^^^^^^^^^^^^^^^^^^^^^^^^^^^^^^^^^^^^^^^
  File "C:\Users\HUAWEI\OneDrive\Рабочий стол\e_store\venv\Lib\site-packages\django\shortcuts.py", line 24, in render
    content = loader.render_to_string(template_name, context, request, using=using)
              ^^^^^^^^^^^^^^^^^^^^^^^^^^^^^^^^^^^^^^^^^^^^^^^^^^^^^^^^^^^^^^^^^^^^^
  File "C:\Users\HUAWEI\OneDrive\Рабочий стол\e_store\venv\Lib\site-packages\django\template\loader.py", line 62, in render_to_string
    return template.render(context, request)
           ^^^^^^^^^^^^^^^^^^^^^^^^^^^^^^^^^
  File "C:\Users\HUAWEI\OneDrive\Рабочий стол\e_store\venv\Lib\site-packages\django\template\backends\django.py", line 63, in render
    reraise(exc, self.backend)
  File "C:\Users\HUAWEI\OneDrive\Рабочий стол\e_store\venv\Lib\site-packages\django\template\backends\django.py", line 84, in reraise
    raise new from exc
django.template.exceptions.TemplateDoesNotExist: base.html
ERROR 2024-01-28 13:37:06,696 basehttp 26968 13704 "GET /add_good/ HTTP/1.1" 500 131523
INFO 2024-01-28 13:39:10,597 basehttp 26968 13704 "GET /add_good/ HTTP/1.1" 200 1278
ERROR 2024-01-28 13:39:51,780 log 26968 24344 Internal Server Error: /add_good/
Traceback (most recent call last):
  File "C:\Users\HUAWEI\OneDrive\Рабочий стол\e_store\venv\Lib\site-packages\django\core\handlers\exception.py", line 55, in inner
    response = get_response(request)
               ^^^^^^^^^^^^^^^^^^^^^
  File "C:\Users\HUAWEI\OneDrive\Рабочий стол\e_store\venv\Lib\site-packages\django\core\handlers\base.py", line 204, in _get_response
    self.check_response(response, callback)
  File "C:\Users\HUAWEI\OneDrive\Рабочий стол\e_store\venv\Lib\site-packages\django\core\handlers\base.py", line 332, in check_response
    raise ValueError(
ValueError: The view mainapp.views.create_good didn't return an HttpResponse object. It returned None instead.
ERROR 2024-01-28 13:39:51,781 basehttp 26968 24344 "POST /add_good/ HTTP/1.1" 500 68128
INFO 2024-01-28 15:10:12,958 autoreload 19164 15416 Watching for file changes with StatReloader
ERROR 2024-01-28 15:10:19,340 log 19164 17308 Internal Server Error: /add_good/
Traceback (most recent call last):
  File "C:\Users\HUAWEI\OneDrive\Рабочий стол\e_store\venv\Lib\site-packages\django\core\handlers\exception.py", line 55, in inner
    response = get_response(request)
               ^^^^^^^^^^^^^^^^^^^^^
  File "C:\Users\HUAWEI\OneDrive\Рабочий стол\e_store\venv\Lib\site-packages\django\core\handlers\base.py", line 204, in _get_response
    self.check_response(response, callback)
  File "C:\Users\HUAWEI\OneDrive\Рабочий стол\e_store\venv\Lib\site-packages\django\core\handlers\base.py", line 332, in check_response
    raise ValueError(
ValueError: The view mainapp.views.create_good didn't return an HttpResponse object. It returned None instead.
ERROR 2024-01-28 15:10:19,341 basehttp 19164 17308 "POST /add_good/ HTTP/1.1" 500 68128
INFO 2024-01-28 15:11:02,946 autoreload 19164 15416 C:\Users\HUAWEI\OneDrive\Рабочий стол\e_store\e_store\mainapp\views.py changed, reloading.
INFO 2024-01-28 15:11:04,008 autoreload 12348 28968 Watching for file changes with StatReloader
ERROR 2024-01-28 15:11:04,593 log 12348 28352 Internal Server Error: /add_good/
Traceback (most recent call last):
  File "C:\Users\HUAWEI\OneDrive\Рабочий стол\e_store\venv\Lib\site-packages\django\core\handlers\exception.py", line 55, in inner
    response = get_response(request)
               ^^^^^^^^^^^^^^^^^^^^^
  File "C:\Users\HUAWEI\OneDrive\Рабочий стол\e_store\venv\Lib\site-packages\django\core\handlers\base.py", line 204, in _get_response
    self.check_response(response, callback)
  File "C:\Users\HUAWEI\OneDrive\Рабочий стол\e_store\venv\Lib\site-packages\django\core\handlers\base.py", line 332, in check_response
    raise ValueError(
ValueError: The view mainapp.views.create_good didn't return an HttpResponse object. It returned None instead.
ERROR 2024-01-28 15:11:04,593 basehttp 12348 28352 "POST /add_good/ HTTP/1.1" 500 68128
INFO 2024-01-28 15:11:19,735 autoreload 12348 28968 C:\Users\HUAWEI\OneDrive\Рабочий стол\e_store\e_store\mainapp\views.py changed, reloading.
INFO 2024-01-28 15:11:20,316 autoreload 29248 16124 Watching for file changes with StatReloader
INFO 2024-01-28 15:11:21,486 basehttp 29248 10796 "POST /add_good/ HTTP/1.1" 200 27
INFO 2024-01-28 15:12:22,280 autoreload 29248 16124 C:\Users\HUAWEI\OneDrive\Рабочий стол\e_store\e_store\mainapp\views.py changed, reloading.
INFO 2024-01-28 15:12:22,758 autoreload 18616 29288 Watching for file changes with StatReloader
INFO 2024-01-28 15:13:24,680 autoreload 18616 29288 C:\Users\HUAWEI\OneDrive\Рабочий стол\e_store\e_store\mainapp\views.py changed, reloading.
INFO 2024-01-28 15:13:25,255 autoreload 14272 13496 Watching for file changes with StatReloader
INFO 2024-01-28 15:14:42,887 autoreload 14272 13496 C:\Users\HUAWEI\OneDrive\Рабочий стол\e_store\e_store\mainapp\urls.py changed, reloading.
INFO 2024-01-28 15:14:43,339 autoreload 24680 27116 Watching for file changes with StatReloader
INFO 2024-01-28 15:15:54,607 autoreload 24680 27116 C:\Users\HUAWEI\OneDrive\Рабочий стол\e_store\e_store\mainapp\urls.py changed, reloading.
INFO 2024-01-28 15:15:55,140 autoreload 8180 24464 Watching for file changes with StatReloader
INFO 2024-01-28 15:15:55,460 basehttp 8180 27844 "GET / HTTP/1.1" 200 117
INFO 2024-01-28 15:16:02,903 basehttp 8180 10504 "GET /add_good/ HTTP/1.1" 200 1278
INFO 2024-01-28 15:16:20,170 basehttp 8180 2176 "POST /add_good/ HTTP/1.1" 200 27
INFO 2024-01-28 15:17:23,601 basehttp 8180 9200 "GET /all_goods HTTP/1.1" 301 0
INFO 2024-01-28 15:17:23,612 basehttp 8180 10796 "GET /all_goods/ HTTP/1.1" 200 33
INFO 2024-01-28 15:21:42,806 autoreload 8180 24464 C:\Users\HUAWEI\OneDrive\Рабочий стол\e_store\e_store\mainapp\forms.py changed, reloading.
INFO 2024-01-28 15:21:43,407 autoreload 9364 5780 Watching for file changes with StatReloader
INFO 2024-01-28 15:22:17,606 autoreload 9364 5780 C:\Users\HUAWEI\OneDrive\Рабочий стол\e_store\e_store\mainapp\forms.py changed, reloading.
INFO 2024-01-28 15:22:18,075 autoreload 18280 15336 Watching for file changes with StatReloader
INFO 2024-01-28 15:22:36,882 autoreload 18280 15336 C:\Users\HUAWEI\OneDrive\Рабочий стол\e_store\e_store\mainapp\forms.py changed, reloading.
INFO 2024-01-28 15:22:37,465 autoreload 1696 3728 Watching for file changes with StatReloader
INFO 2024-01-28 15:23:54,840 autoreload 1696 3728 C:\Users\HUAWEI\OneDrive\Рабочий стол\e_store\e_store\mainapp\forms.py changed, reloading.
INFO 2024-01-28 15:23:55,351 autoreload 28380 25512 Watching for file changes with StatReloader
INFO 2024-01-28 15:24:37,906 autoreload 28380 25512 C:\Users\HUAWEI\OneDrive\Рабочий стол\e_store\e_store\mainapp\views.py changed, reloading.
INFO 2024-01-28 15:24:38,491 autoreload 16224 24624 Watching for file changes with StatReloader
ERROR 2024-01-28 15:24:45,302 log 16224 19632 Internal Server Error: /add_good/
Traceback (most recent call last):
  File "C:\Users\HUAWEI\OneDrive\Рабочий стол\e_store\venv\Lib\site-packages\django\core\handlers\exception.py", line 55, in inner
    response = get_response(request)
               ^^^^^^^^^^^^^^^^^^^^^
  File "C:\Users\HUAWEI\OneDrive\Рабочий стол\e_store\venv\Lib\site-packages\django\core\handlers\base.py", line 197, in _get_response
    response = wrapped_callback(request, *callback_args, **callback_kwargs)
               ^^^^^^^^^^^^^^^^^^^^^^^^^^^^^^^^^^^^^^^^^^^^^^^^^^^^^^^^^^^^
  File "C:\Users\HUAWEI\OneDrive\Рабочий стол\e_store\e_store\mainapp\views.py", line 56, in create_good
    form = GoodForm()
           ^^^^^^^^^^
  File "C:\Users\HUAWEI\OneDrive\Рабочий стол\e_store\venv\Lib\site-packages\django\forms\models.py", line 350, in __init__
    raise ValueError("ModelForm has no model class specified.")
ValueError: ModelForm has no model class specified.
ERROR 2024-01-28 15:24:45,305 basehttp 16224 19632 "GET /add_good/ HTTP/1.1" 500 71920
INFO 2024-01-28 15:25:36,398 autoreload 16224 24624 C:\Users\HUAWEI\OneDrive\Рабочий стол\e_store\e_store\mainapp\forms.py changed, reloading.
INFO 2024-01-28 15:25:37,034 autoreload 10664 24824 Watching for file changes with StatReloader
INFO 2024-01-28 15:26:44,123 autoreload 10664 24824 C:\Users\HUAWEI\OneDrive\Рабочий стол\e_store\e_store\mainapp\views.py changed, reloading.
INFO 2024-01-28 15:26:44,624 autoreload 28184 20136 Watching for file changes with StatReloader
INFO 2024-01-28 15:26:44,793 basehttp 28184 25792 "GET /add_good/ HTTP/1.1" 200 1276
ERROR 2024-01-28 15:27:10,510 log 28184 12812 Internal Server Error: /add_good/
Traceback (most recent call last):
  File "C:\Users\HUAWEI\OneDrive\Рабочий стол\e_store\venv\Lib\site-packages\django\core\handlers\exception.py", line 55, in inner
    response = get_response(request)
               ^^^^^^^^^^^^^^^^^^^^^
  File "C:\Users\HUAWEI\OneDrive\Рабочий стол\e_store\venv\Lib\site-packages\django\core\handlers\base.py", line 204, in _get_response
    self.check_response(response, callback)
  File "C:\Users\HUAWEI\OneDrive\Рабочий стол\e_store\venv\Lib\site-packages\django\core\handlers\base.py", line 332, in check_response
    raise ValueError(
ValueError: The view mainapp.views.create_good didn't return an HttpResponse object. It returned None instead.
ERROR 2024-01-28 15:27:10,511 basehttp 28184 12812 "POST /add_good/ HTTP/1.1" 500 68118
INFO 2024-01-28 15:29:46,324 basehttp 28184 27692 "GET /all_goods/ HTTP/1.1" 200 33
INFO 2024-01-28 15:29:47,924 basehttp 28184 27692 "GET /all_goods/ HTTP/1.1" 200 33
INFO 2024-01-28 15:31:51,133 autoreload 28184 20136 C:\Users\HUAWEI\OneDrive\Рабочий стол\e_store\e_store\mainapp\views.py changed, reloading.
INFO 2024-01-28 15:31:51,711 autoreload 11344 15172 Watching for file changes with StatReloader
INFO 2024-01-28 15:31:58,017 basehttp 11344 15040 "GET /add_good/ HTTP/1.1" 200 1276
ERROR 2024-01-28 15:32:07,727 log 11344 19744 Internal Server Error: /add_good/
Traceback (most recent call last):
  File "C:\Users\HUAWEI\OneDrive\Рабочий стол\e_store\venv\Lib\site-packages\django\core\handlers\exception.py", line 55, in inner
    response = get_response(request)
               ^^^^^^^^^^^^^^^^^^^^^
  File "C:\Users\HUAWEI\OneDrive\Рабочий стол\e_store\venv\Lib\site-packages\django\core\handlers\base.py", line 204, in _get_response
    self.check_response(response, callback)
  File "C:\Users\HUAWEI\OneDrive\Рабочий стол\e_store\venv\Lib\site-packages\django\core\handlers\base.py", line 332, in check_response
    raise ValueError(
ValueError: The view mainapp.views.create_good didn't return an HttpResponse object. It returned None instead.
ERROR 2024-01-28 15:32:07,729 basehttp 11344 19744 "POST /add_good/ HTTP/1.1" 500 68113
INFO 2024-01-28 15:32:17,459 autoreload 11344 15172 C:\Users\HUAWEI\OneDrive\Рабочий стол\e_store\e_store\mainapp\views.py changed, reloading.
INFO 2024-01-28 15:32:18,033 autoreload 12644 19488 Watching for file changes with StatReloader
INFO 2024-01-28 15:32:19,144 basehttp 12644 10304 "POST /add_good/ HTTP/1.1" 200 27
INFO 2024-01-28 15:32:27,790 basehttp 12644 8168 "GET /all_goods/ HTTP/1.1" 200 33
INFO 2024-01-28 15:47:14,357 basehttp 12644 16488 "GET / HTTP/1.1" 200 117
INFO 2024-01-28 15:47:22,402 basehttp 12644 16488 "GET /add_good/ HTTP/1.1" 200 1276
INFO 2024-01-28 15:47:31,974 basehttp 12644 25884 "POST /add_good/ HTTP/1.1" 200 27
INFO 2024-01-28 15:47:47,155 autoreload 12644 19488 C:\Users\HUAWEI\OneDrive\Рабочий стол\e_store\e_store\mainapp\views.py changed, reloading.
INFO 2024-01-28 15:47:47,861 autoreload 25888 22308 Watching for file changes with StatReloader
INFO 2024-01-28 15:47:48,651 basehttp 25888 23860 "GET /add_good/ HTTP/1.1" 200 1276
ERROR 2024-01-28 15:47:50,051 log 25888 23860 Internal Server Error: /add_good/
Traceback (most recent call last):
  File "C:\Users\HUAWEI\OneDrive\Рабочий стол\e_store\venv\Lib\site-packages\django\core\handlers\exception.py", line 55, in inner
    response = get_response(request)
               ^^^^^^^^^^^^^^^^^^^^^
  File "C:\Users\HUAWEI\OneDrive\Рабочий стол\e_store\venv\Lib\site-packages\django\core\handlers\base.py", line 204, in _get_response
    self.check_response(response, callback)
  File "C:\Users\HUAWEI\OneDrive\Рабочий стол\e_store\venv\Lib\site-packages\django\core\handlers\base.py", line 332, in check_response
    raise ValueError(
ValueError: The view mainapp.views.create_good didn't return an HttpResponse object. It returned None instead.
ERROR 2024-01-28 15:47:50,052 basehttp 25888 23860 "POST /add_good/ HTTP/1.1" 500 68115
INFO 2024-01-28 15:53:46,629 autoreload 25888 22308 C:\Users\HUAWEI\OneDrive\Рабочий стол\e_store\e_store\mainapp\views.py changed, reloading.
INFO 2024-01-28 15:53:47,502 autoreload 19180 23800 Watching for file changes with StatReloader
INFO 2024-01-28 15:53:51,720 basehttp 19180 20248 "POST /add_good/ HTTP/1.1" 200 31
INFO 2024-01-28 15:55:11,185 autoreload 19180 23800 C:\Users\HUAWEI\OneDrive\Рабочий стол\e_store\e_store\mainapp\views.py changed, reloading.
INFO 2024-01-28 15:55:11,755 autoreload 27924 19364 Watching for file changes with StatReloader
INFO 2024-01-28 15:55:12,183 basehttp 27924 9172 "GET /add_good/ HTTP/1.1" 200 1276
INFO 2024-01-28 15:55:13,082 basehttp 27924 9172 "POST /add_good/ HTTP/1.1" 200 27
INFO 2024-01-28 17:33:13,825 autoreload 8180 25208 Watching for file changes with StatReloader
INFO 2024-01-28 17:33:15,308 basehttp 8180 8960 "GET / HTTP/1.1" 200 117
INFO 2024-01-28 17:33:19,196 basehttp 8180 3448 "GET /add_good/ HTTP/1.1" 200 1276
INFO 2024-01-28 17:33:44,412 basehttp 8180 9524 "POST /add_good/ HTTP/1.1" 200 27
INFO 2024-01-28 17:34:25,104 basehttp 8180 21764 "GET /all_goods HTTP/1.1" 301 0
INFO 2024-01-28 17:34:25,120 basehttp 8180 21868 "GET /all_goods/ HTTP/1.1" 200 69
INFO 2024-01-28 20:49:26,309 autoreload 25888 22048 Watching for file changes with StatReloader
INFO 2024-01-28 20:49:27,725 basehttp 25888 24600 "GET / HTTP/1.1" 200 117
ERROR 2024-01-28 20:49:34,890 log 25888 27148 Internal Server Error: /add_good/
Traceback (most recent call last):
  File "C:\Users\HUAWEI\OneDrive\Рабочий стол\e_store\venv\Lib\site-packages\django\core\handlers\exception.py", line 55, in inner
    response = get_response(request)
               ^^^^^^^^^^^^^^^^^^^^^
  File "C:\Users\HUAWEI\OneDrive\Рабочий стол\e_store\venv\Lib\site-packages\django\core\handlers\base.py", line 197, in _get_response
    response = wrapped_callback(request, *callback_args, **callback_kwargs)
               ^^^^^^^^^^^^^^^^^^^^^^^^^^^^^^^^^^^^^^^^^^^^^^^^^^^^^^^^^^^^
  File "C:\Users\HUAWEI\OneDrive\Рабочий стол\e_store\e_store\mainapp\views.py", line 60, in create_good
    form = GoodForm()
           ^^^^^^^^^^
  File "C:\Users\HUAWEI\OneDrive\Рабочий стол\e_store\venv\Lib\site-packages\django\forms\models.py", line 350, in __init__
    raise ValueError("ModelForm has no model class specified.")
ValueError: ModelForm has no model class specified.
ERROR 2024-01-28 20:49:34,892 basehttp 25888 27148 "GET /add_good/ HTTP/1.1" 500 71950
INFO 2024-01-28 20:49:54,131 autoreload 25888 22048 C:\Users\HUAWEI\OneDrive\Рабочий стол\e_store\e_store\mainapp\forms.py changed, reloading.
INFO 2024-01-28 20:49:54,897 autoreload 24588 26196 Watching for file changes with StatReloader
INFO 2024-01-28 20:49:55,180 basehttp 24588 3160 "GET /add_good/ HTTP/1.1" 200 1228
ERROR 2024-01-28 20:50:29,031 log 24588 14080 Internal Server Error: /add_good/
Traceback (most recent call last):
  File "C:\Users\HUAWEI\OneDrive\Рабочий стол\e_store\venv\Lib\site-packages\django\utils\datastructures.py", line 84, in __getitem__
    list_ = super().__getitem__(key)
            ^^^^^^^^^^^^^^^^^^^^^^^^
KeyError: 'count'

During handling of the above exception, another exception occurred:

Traceback (most recent call last):
  File "C:\Users\HUAWEI\OneDrive\Рабочий стол\e_store\venv\Lib\site-packages\django\core\handlers\exception.py", line 55, in inner
    response = get_response(request)
               ^^^^^^^^^^^^^^^^^^^^^
  File "C:\Users\HUAWEI\OneDrive\Рабочий стол\e_store\venv\Lib\site-packages\django\core\handlers\base.py", line 197, in _get_response
    response = wrapped_callback(request, *callback_args, **callback_kwargs)
               ^^^^^^^^^^^^^^^^^^^^^^^^^^^^^^^^^^^^^^^^^^^^^^^^^^^^^^^^^^^^
  File "C:\Users\HUAWEI\OneDrive\Рабочий стол\e_store\e_store\mainapp\views.py", line 49, in create_good
    count = request.POST['count']
            ~~~~~~~~~~~~^^^^^^^^^
  File "C:\Users\HUAWEI\OneDrive\Рабочий стол\e_store\venv\Lib\site-packages\django\utils\datastructures.py", line 86, in __getitem__
    raise MultiValueDictKeyError(key)
django.utils.datastructures.MultiValueDictKeyError: 'count'
ERROR 2024-01-28 20:50:29,034 basehttp 24588 14080 "POST /add_good/ HTTP/1.1" 500 76801
INFO 2024-01-28 20:50:57,022 autoreload 24588 26196 C:\Users\HUAWEI\OneDrive\Рабочий стол\e_store\e_store\mainapp\forms.py changed, reloading.
INFO 2024-01-28 20:50:57,695 autoreload 27672 996 Watching for file changes with StatReloader
INFO 2024-01-28 20:52:07,973 autoreload 27672 996 C:\Users\HUAWEI\OneDrive\Рабочий стол\e_store\e_store\mainapp\forms.py changed, reloading.
INFO 2024-01-28 20:52:08,508 autoreload 1308 20880 Watching for file changes with StatReloader
ERROR 2024-01-28 20:52:10,331 log 1308 2804 Internal Server Error: /add_good/
Traceback (most recent call last):
  File "C:\Users\HUAWEI\OneDrive\Рабочий стол\e_store\venv\Lib\site-packages\django\utils\datastructures.py", line 84, in __getitem__
    list_ = super().__getitem__(key)
            ^^^^^^^^^^^^^^^^^^^^^^^^
KeyError: 'count'

During handling of the above exception, another exception occurred:

Traceback (most recent call last):
  File "C:\Users\HUAWEI\OneDrive\Рабочий стол\e_store\venv\Lib\site-packages\django\core\handlers\exception.py", line 55, in inner
    response = get_response(request)
               ^^^^^^^^^^^^^^^^^^^^^
  File "C:\Users\HUAWEI\OneDrive\Рабочий стол\e_store\venv\Lib\site-packages\django\core\handlers\base.py", line 197, in _get_response
    response = wrapped_callback(request, *callback_args, **callback_kwargs)
               ^^^^^^^^^^^^^^^^^^^^^^^^^^^^^^^^^^^^^^^^^^^^^^^^^^^^^^^^^^^^
  File "C:\Users\HUAWEI\OneDrive\Рабочий стол\e_store\e_store\mainapp\views.py", line 49, in create_good
    count = request.POST['count']
            ~~~~~~~~~~~~^^^^^^^^^
  File "C:\Users\HUAWEI\OneDrive\Рабочий стол\e_store\venv\Lib\site-packages\django\utils\datastructures.py", line 86, in __getitem__
    raise MultiValueDictKeyError(key)
django.utils.datastructures.MultiValueDictKeyError: 'count'
ERROR 2024-01-28 20:52:10,341 basehttp 1308 2804 "POST /add_good/ HTTP/1.1" 500 76800
INFO 2024-01-28 20:53:08,789 autoreload 1308 20880 C:\Users\HUAWEI\OneDrive\Рабочий стол\e_store\e_store\mainapp\views.py changed, reloading.
INFO 2024-01-28 20:53:09,377 autoreload 29628 20316 Watching for file changes with StatReloader
INFO 2024-01-28 20:53:27,247 autoreload 29628 20316 C:\Users\HUAWEI\OneDrive\Рабочий стол\e_store\e_store\mainapp\views.py changed, reloading.
INFO 2024-01-28 20:53:27,850 autoreload 8904 20660 Watching for file changes with StatReloader
ERROR 2024-01-28 20:53:31,387 log 8904 13444 Internal Server Error: /add_good/
Traceback (most recent call last):
  File "C:\Users\HUAWEI\OneDrive\Рабочий стол\e_store\venv\Lib\site-packages\django\core\handlers\exception.py", line 55, in inner
    response = get_response(request)
               ^^^^^^^^^^^^^^^^^^^^^
  File "C:\Users\HUAWEI\OneDrive\Рабочий стол\e_store\venv\Lib\site-packages\django\core\handlers\base.py", line 197, in _get_response
    response = wrapped_callback(request, *callback_args, **callback_kwargs)
               ^^^^^^^^^^^^^^^^^^^^^^^^^^^^^^^^^^^^^^^^^^^^^^^^^^^^^^^^^^^^
  File "C:\Users\HUAWEI\OneDrive\Рабочий стол\e_store\e_store\mainapp\views.py", line 51, in create_good
    name = form.cleaned_data['name']
           ^^^^^^^^^^^^^^^^^
AttributeError: 'GoodForm' object has no attribute 'cleaned_data'
ERROR 2024-01-28 20:53:31,390 basehttp 8904 13444 "POST /add_good/ HTTP/1.1" 500 67816
INFO 2024-01-28 20:54:11,034 autoreload 8904 20660 C:\Users\HUAWEI\OneDrive\Рабочий стол\e_store\e_store\mainapp\views.py changed, reloading.
INFO 2024-01-28 20:54:11,584 autoreload 7016 17136 Watching for file changes with StatReloader
ERROR 2024-01-28 20:54:14,874 log 7016 13460 Internal Server Error: /add_good/
Traceback (most recent call last):
  File "C:\Users\HUAWEI\OneDrive\Рабочий стол\e_store\venv\Lib\site-packages\django\utils\datastructures.py", line 84, in __getitem__
    list_ = super().__getitem__(key)
            ^^^^^^^^^^^^^^^^^^^^^^^^
KeyError: 'count'

During handling of the above exception, another exception occurred:

Traceback (most recent call last):
  File "C:\Users\HUAWEI\OneDrive\Рабочий стол\e_store\venv\Lib\site-packages\django\core\handlers\exception.py", line 55, in inner
    response = get_response(request)
               ^^^^^^^^^^^^^^^^^^^^^
  File "C:\Users\HUAWEI\OneDrive\Рабочий стол\e_store\venv\Lib\site-packages\django\core\handlers\base.py", line 197, in _get_response
    response = wrapped_callback(request, *callback_args, **callback_kwargs)
               ^^^^^^^^^^^^^^^^^^^^^^^^^^^^^^^^^^^^^^^^^^^^^^^^^^^^^^^^^^^^
  File "C:\Users\HUAWEI\OneDrive\Рабочий стол\e_store\e_store\mainapp\views.py", line 49, in create_good
    count = request.POST['count']
            ~~~~~~~~~~~~^^^^^^^^^
  File "C:\Users\HUAWEI\OneDrive\Рабочий стол\e_store\venv\Lib\site-packages\django\utils\datastructures.py", line 86, in __getitem__
    raise MultiValueDictKeyError(key)
django.utils.datastructures.MultiValueDictKeyError: 'count'
ERROR 2024-01-28 20:54:14,876 basehttp 7016 13460 "POST /add_good/ HTTP/1.1" 500 76765
INFO 2024-02-01 19:05:57,490 autoreload 7144 11984 Watching for file changes with StatReloader
INFO 2024-02-01 19:05:59,115 basehttp 7144 17516 "GET / HTTP/1.1" 200 117
WARNING 2024-02-01 19:05:59,209 log 7144 17516 Not Found: /favicon.ico
WARNING 2024-02-01 19:05:59,210 basehttp 7144 17516 "GET /favicon.ico HTTP/1.1" 404 3353
INFO 2024-02-01 19:06:06,168 basehttp 7144 20692 "GET /add_good/ HTTP/1.1" 200 1215
ERROR 2024-02-01 19:06:25,666 log 7144 22992 Internal Server Error: /add_good/
Traceback (most recent call last):
  File "C:\Users\HUAWEI\OneDrive\Рабочий стол\e_store\venv\Lib\site-packages\django\utils\datastructures.py", line 84, in __getitem__
    list_ = super().__getitem__(key)
            ^^^^^^^^^^^^^^^^^^^^^^^^
KeyError: 'image'

During handling of the above exception, another exception occurred:

Traceback (most recent call last):
  File "C:\Users\HUAWEI\OneDrive\Рабочий стол\e_store\venv\Lib\site-packages\django\core\handlers\exception.py", line 55, in inner
    response = get_response(request)
               ^^^^^^^^^^^^^^^^^^^^^
  File "C:\Users\HUAWEI\OneDrive\Рабочий стол\e_store\venv\Lib\site-packages\django\core\handlers\base.py", line 197, in _get_response
    response = wrapped_callback(request, *callback_args, **callback_kwargs)
               ^^^^^^^^^^^^^^^^^^^^^^^^^^^^^^^^^^^^^^^^^^^^^^^^^^^^^^^^^^^^
  File "C:\Users\HUAWEI\OneDrive\Рабочий стол\e_store\e_store\mainapp\views.py", line 50, in create_good
    image = request.POST['image']
            ~~~~~~~~~~~~^^^^^^^^^
  File "C:\Users\HUAWEI\OneDrive\Рабочий стол\e_store\venv\Lib\site-packages\django\utils\datastructures.py", line 86, in __getitem__
    raise MultiValueDictKeyError(key)
django.utils.datastructures.MultiValueDictKeyError: 'image'
ERROR 2024-02-01 19:06:25,668 basehttp 7144 22992 "POST /add_good/ HTTP/1.1" 500 76972
INFO 2024-02-01 19:10:09,508 autoreload 14760 21168 Watching for file changes with StatReloader
INFO 2024-02-01 19:10:12,400 basehttp 14760 4064 "GET / HTTP/1.1" 200 117
INFO 2024-02-01 19:10:17,307 basehttp 14760 4064 "GET /all_goods HTTP/1.1" 301 0
INFO 2024-02-01 19:10:17,317 basehttp 14760 9848 "GET /all_goods/ HTTP/1.1" 200 69
INFO 2024-02-01 19:10:26,192 basehttp 14760 9848 "GET /add_good/ HTTP/1.1" 200 1216
ERROR 2024-02-01 19:10:39,370 log 14760 9848 Internal Server Error: /add_good/
Traceback (most recent call last):
  File "C:\Users\HUAWEI\OneDrive\Рабочий стол\e_store\venv\Lib\site-packages\django\utils\datastructures.py", line 84, in __getitem__
    list_ = super().__getitem__(key)
            ^^^^^^^^^^^^^^^^^^^^^^^^
KeyError: 'image'

During handling of the above exception, another exception occurred:

Traceback (most recent call last):
  File "C:\Users\HUAWEI\OneDrive\Рабочий стол\e_store\venv\Lib\site-packages\django\core\handlers\exception.py", line 55, in inner
    response = get_response(request)
               ^^^^^^^^^^^^^^^^^^^^^
  File "C:\Users\HUAWEI\OneDrive\Рабочий стол\e_store\venv\Lib\site-packages\django\core\handlers\base.py", line 197, in _get_response
    response = wrapped_callback(request, *callback_args, **callback_kwargs)
               ^^^^^^^^^^^^^^^^^^^^^^^^^^^^^^^^^^^^^^^^^^^^^^^^^^^^^^^^^^^^
  File "C:\Users\HUAWEI\OneDrive\Рабочий стол\e_store\e_store\mainapp\views.py", line 50, in create_good
    image = request.POST['image']
            ~~~~~~~~~~~~^^^^^^^^^
  File "C:\Users\HUAWEI\OneDrive\Рабочий стол\e_store\venv\Lib\site-packages\django\utils\datastructures.py", line 86, in __getitem__
    raise MultiValueDictKeyError(key)
django.utils.datastructures.MultiValueDictKeyError: 'image'
ERROR 2024-02-01 19:10:39,375 basehttp 14760 9848 "POST /add_good/ HTTP/1.1" 500 76972
WARNING 2024-02-01 20:00:32,358 log 14760 22664 Not Found: /favicon.ico
WARNING 2024-02-01 20:00:32,361 basehttp 14760 22664 "GET /favicon.ico HTTP/1.1" 404 3353
INFO 2024-02-01 20:05:01,752 autoreload 14760 21168 C:\Users\HUAWEI\OneDrive\Рабочий стол\e_store\e_store\mainapp\views.py changed, reloading.
INFO 2024-02-01 20:05:03,406 autoreload 22728 5372 Watching for file changes with StatReloader
ERROR 2024-02-01 20:05:07,631 log 22728 21324 Internal Server Error: /add_good/
Traceback (most recent call last):
  File "C:\Users\HUAWEI\OneDrive\Рабочий стол\e_store\venv\Lib\site-packages\django\core\handlers\exception.py", line 55, in inner
    response = get_response(request)
               ^^^^^^^^^^^^^^^^^^^^^
  File "C:\Users\HUAWEI\OneDrive\Рабочий стол\e_store\venv\Lib\site-packages\django\core\handlers\base.py", line 197, in _get_response
    response = wrapped_callback(request, *callback_args, **callback_kwargs)
               ^^^^^^^^^^^^^^^^^^^^^^^^^^^^^^^^^^^^^^^^^^^^^^^^^^^^^^^^^^^^
  File "C:\Users\HUAWEI\OneDrive\Рабочий стол\e_store\e_store\mainapp\views.py", line 52, in create_good
    good.save()
  File "C:\Users\HUAWEI\OneDrive\Рабочий стол\e_store\venv\Lib\site-packages\django\db\models\base.py", line 814, in save
    self.save_base(
  File "C:\Users\HUAWEI\OneDrive\Рабочий стол\e_store\venv\Lib\site-packages\django\db\models\base.py", line 877, in save_base
    updated = self._save_table(
              ^^^^^^^^^^^^^^^^^
  File "C:\Users\HUAWEI\OneDrive\Рабочий стол\e_store\venv\Lib\site-packages\django\db\models\base.py", line 1020, in _save_table
    results = self._do_insert(
              ^^^^^^^^^^^^^^^^
  File "C:\Users\HUAWEI\OneDrive\Рабочий стол\e_store\venv\Lib\site-packages\django\db\models\base.py", line 1061, in _do_insert
    return manager._insert(
           ^^^^^^^^^^^^^^^^
  File "C:\Users\HUAWEI\OneDrive\Рабочий стол\e_store\venv\Lib\site-packages\django\db\models\manager.py", line 87, in manager_method
    return getattr(self.get_queryset(), name)(*args, **kwargs)
           ^^^^^^^^^^^^^^^^^^^^^^^^^^^^^^^^^^^^^^^^^^^^^^^^^^^
  File "C:\Users\HUAWEI\OneDrive\Рабочий стол\e_store\venv\Lib\site-packages\django\db\models\query.py", line 1805, in _insert
    return query.get_compiler(using=using).execute_sql(returning_fields)
           ^^^^^^^^^^^^^^^^^^^^^^^^^^^^^^^^^^^^^^^^^^^^^^^^^^^^^^^^^^^^^
  File "C:\Users\HUAWEI\OneDrive\Рабочий стол\e_store\venv\Lib\site-packages\django\db\models\sql\compiler.py", line 1821, in execute_sql
    for sql, params in self.as_sql():
                       ^^^^^^^^^^^^^
  File "C:\Users\HUAWEI\OneDrive\Рабочий стол\e_store\venv\Lib\site-packages\django\db\models\sql\compiler.py", line 1745, in as_sql
    value_rows = [
                 ^
  File "C:\Users\HUAWEI\OneDrive\Рабочий стол\e_store\venv\Lib\site-packages\django\db\models\sql\compiler.py", line 1746, in <listcomp>
    [
  File "C:\Users\HUAWEI\OneDrive\Рабочий стол\e_store\venv\Lib\site-packages\django\db\models\sql\compiler.py", line 1747, in <listcomp>
    self.prepare_value(field, self.pre_save_val(field, obj))
  File "C:\Users\HUAWEI\OneDrive\Рабочий стол\e_store\venv\Lib\site-packages\django\db\models\sql\compiler.py", line 1686, in prepare_value
    return field.get_db_prep_save(value, connection=self.connection)
           ^^^^^^^^^^^^^^^^^^^^^^^^^^^^^^^^^^^^^^^^^^^^^^^^^^^^^^^^^
  File "C:\Users\HUAWEI\OneDrive\Рабочий стол\e_store\venv\Lib\site-packages\django\db\models\fields\__init__.py", line 1759, in get_db_prep_save
    return connection.ops.adapt_decimalfield_value(
           ^^^^^^^^^^^^^^^^^^^^^^^^^^^^^^^^^^^^^^^^
  File "C:\Users\HUAWEI\OneDrive\Рабочий стол\e_store\venv\Lib\site-packages\django\db\backends\base\operations.py", line 574, in adapt_decimalfield_value
    return utils.format_number(value, max_digits, decimal_places)
           ^^^^^^^^^^^^^^^^^^^^^^^^^^^^^^^^^^^^^^^^^^^^^^^^^^^^^^
  File "C:\Users\HUAWEI\OneDrive\Рабочий стол\e_store\venv\Lib\site-packages\django\db\backends\utils.py", line 304, in format_number
    value = value.quantize(
            ^^^^^^^^^^^^^^^
decimal.InvalidOperation: [<class 'decimal.InvalidOperation'>]
ERROR 2024-02-01 20:05:07,636 basehttp 22728 21324 "POST /add_good/ HTTP/1.1" 500 136967
INFO 2024-02-01 20:06:19,855 autoreload 22728 5372 C:\Users\HUAWEI\OneDrive\Рабочий стол\e_store\e_store\mainapp\forms.py changed, reloading.
INFO 2024-02-01 20:06:20,561 autoreload 11072 1124 Watching for file changes with StatReloader
INFO 2024-02-01 20:06:21,367 basehttp 11072 2780 "POST /add_good/ HTTP/1.1" 200 31
INFO 2024-02-01 20:09:43,454 autoreload 11072 1124 C:\Users\HUAWEI\OneDrive\Рабочий стол\e_store\e_store\mainapp\views.py changed, reloading.
INFO 2024-02-01 20:09:44,115 autoreload 17936 11592 Watching for file changes with StatReloader
INFO 2024-02-01 20:09:45,200 basehttp 17936 17468 "POST /add_good/ HTTP/1.1" 200 31
INFO 2024-02-01 20:10:50,105 basehttp 17936 12260 "GET /add_good/ HTTP/1.1" 200 1216
INFO 2024-02-01 20:10:54,160 basehttp 17936 15372 "POST /add_good/ HTTP/1.1" 200 27
INFO 2024-02-02 11:34:30,596 autoreload 22612 13376 Watching for file changes with StatReloader
INFO 2024-02-02 11:34:33,045 basehttp 22612 14892 "GET / HTTP/1.1" 200 117
INFO 2024-02-02 11:35:02,858 basehttp 22612 12192 "GET /admin HTTP/1.1" 301 0
INFO 2024-02-02 11:35:02,913 basehttp 22612 20188 "GET /admin/ HTTP/1.1" 302 0
INFO 2024-02-02 11:35:03,039 basehttp 22612 20188 "GET /admin/login/?next=/admin/ HTTP/1.1" 200 4181
INFO 2024-02-02 11:35:03,400 basehttp 22612 19816 "GET /static/admin/css/dark_mode.css HTTP/1.1" 200 2929
INFO 2024-02-02 11:35:03,405 basehttp 22612 15856 "GET /static/admin/css/nav_sidebar.css HTTP/1.1" 200 2694
INFO 2024-02-02 11:35:03,409 basehttp 22612 22088 "GET /static/admin/css/login.css HTTP/1.1" 200 958
INFO 2024-02-02 11:35:03,409 basehttp 22612 20188 "GET /static/admin/css/base.css HTTP/1.1" 200 21310
INFO 2024-02-02 11:35:03,412 basehttp 22612 9420 "GET /static/admin/css/responsive.css HTTP/1.1" 200 18559
INFO 2024-02-02 11:35:03,433 basehttp 22612 20188 "GET /static/admin/js/theme.js HTTP/1.1" 200 1943
INFO 2024-02-02 11:35:03,446 basehttp 22612 9420 "GET /static/admin/js/nav_sidebar.js HTTP/1.1" 200 3063
INFO 2024-02-02 11:36:14,165 autoreload 22612 13376 C:\Users\HUAWEI\OneDrive\Рабочий стол\e_store\e_store\e_store\settings.py changed, reloading.
INFO 2024-02-02 11:36:14,890 autoreload 21996 22296 Watching for file changes with StatReloader
INFO 2024-02-02 11:37:16,529 basehttp 21996 20968 "POST /admin/login/?next=/admin/ HTTP/1.1" 200 4534
INFO 2024-02-02 11:39:32,596 autoreload 12168 24280 Watching for file changes with StatReloader
INFO 2024-02-02 11:39:42,513 basehttp 12168 23860 "POST /admin/login/?next=/admin/ HTTP/1.1" 302 0
INFO 2024-02-02 11:39:42,651 basehttp 12168 23860 "GET /admin/ HTTP/1.1" 200 7419
INFO 2024-02-02 11:39:42,809 basehttp 12168 19700 "GET /static/admin/css/dashboard.css HTTP/1.1" 200 441
INFO 2024-02-02 11:39:42,834 basehttp 12168 23860 "GET /static/admin/img/icon-changelink.svg HTTP/1.1" 200 380
INFO 2024-02-02 11:39:42,836 basehttp 12168 19700 "GET /static/admin/img/icon-addlink.svg HTTP/1.1" 200 331
INFO 2024-02-02 11:39:53,849 basehttp 12168 19700 "GET /admin/mainapp/good/ HTTP/1.1" 200 15871
INFO 2024-02-02 11:39:53,925 basehttp 12168 23860 "GET /static/admin/css/changelists.css HTTP/1.1" 200 6566
INFO 2024-02-02 11:39:53,931 basehttp 12168 12836 "GET /static/admin/css/forms.css HTTP/1.1" 200 9090
INFO 2024-02-02 11:39:53,942 basehttp 12168 5168 "GET /admin/jsi18n/ HTTP/1.1" 200 16066
INFO 2024-02-02 11:39:53,942 basehttp 12168 9900 "GET /static/admin/js/jquery.init.js HTTP/1.1" 200 347
INFO 2024-02-02 11:39:53,943 basehttp 12168 19700 "GET /static/admin/js/core.js HTTP/1.1" 200 5682
INFO 2024-02-02 11:39:53,959 basehttp 12168 9900 "GET /static/admin/css/widgets.css HTTP/1.1" 200 11921
INFO 2024-02-02 11:39:53,965 basehttp 12168 23860 "GET /static/admin/js/admin/RelatedObjectLookups.js HTTP/1.1" 200 8943
INFO 2024-02-02 11:39:53,968 basehttp 12168 12836 "GET /static/admin/js/actions.js HTTP/1.1" 200 7872
INFO 2024-02-02 11:39:53,970 basehttp 12168 5168 "GET /static/admin/js/prepopulate.js HTTP/1.1" 200 1531
INFO 2024-02-02 11:39:53,971 basehttp 12168 19700 "GET /static/admin/js/urlify.js HTTP/1.1" 200 7887
INFO 2024-02-02 11:39:53,981 basehttp 12168 13144 "GET /static/admin/js/vendor/jquery/jquery.js HTTP/1.1" 200 292458
INFO 2024-02-02 11:39:53,989 basehttp 12168 12836 "GET /static/admin/img/search.svg HTTP/1.1" 200 458
INFO 2024-02-02 11:39:53,994 basehttp 12168 9900 "GET /static/admin/js/vendor/xregexp/xregexp.js HTTP/1.1" 200 232381
INFO 2024-02-02 11:39:54,128 basehttp 12168 13144 "GET /static/admin/js/filters.js HTTP/1.1" 200 978
INFO 2024-02-02 11:39:54,216 basehttp 12168 9900 "GET /static/admin/img/tooltag-add.svg HTTP/1.1" 200 331
INFO 2024-02-02 11:41:36,710 basehttp 12168 24200 "GET /admin/auth/user/add/ HTTP/1.1" 200 12135
INFO 2024-02-02 11:41:36,754 basehttp 12168 14728 "GET /admin/jsi18n/ HTTP/1.1" 200 16066
INFO 2024-02-02 11:41:36,758 basehttp 12168 8404 "GET /static/admin/js/prepopulate_init.js HTTP/1.1" 200 586
INFO 2024-02-02 11:41:36,774 basehttp 12168 14728 "GET /static/admin/js/change_form.js HTTP/1.1" 200 606
INFO 2024-02-02 11:42:29,921 basehttp 12168 14728 "POST /admin/auth/user/add/ HTTP/1.1" 302 0
INFO 2024-02-02 11:42:30,051 basehttp 12168 14728 "GET /admin/auth/user/2/change/ HTTP/1.1" 200 23809
INFO 2024-02-02 11:42:30,094 basehttp 12168 21460 "GET /admin/jsi18n/ HTTP/1.1" 200 16066
INFO 2024-02-02 11:42:30,103 basehttp 12168 22504 "GET /static/admin/js/SelectBox.js HTTP/1.1" 200 4530
INFO 2024-02-02 11:42:30,107 basehttp 12168 19224 "GET /static/admin/js/SelectFilter2.js HTTP/1.1" 200 15292
INFO 2024-02-02 11:42:30,108 basehttp 12168 24200 "GET /static/admin/js/admin/DateTimeShortcuts.js HTTP/1.1" 200 19319
INFO 2024-02-02 11:42:30,113 basehttp 12168 8404 "GET /static/admin/js/calendar.js HTTP/1.1" 200 8466
INFO 2024-02-02 11:42:30,149 basehttp 12168 8404 "GET /static/admin/img/icon-yes.svg HTTP/1.1" 200 436
INFO 2024-02-02 11:42:30,178 basehttp 12168 22504 "GET /static/admin/img/icon-calendar.svg HTTP/1.1" 200 1086
INFO 2024-02-02 11:42:30,179 basehttp 12168 21460 "GET /static/admin/img/icon-clock.svg HTTP/1.1" 200 677
INFO 2024-02-02 11:42:30,180 basehttp 12168 8404 "GET /static/admin/img/icon-unknown.svg HTTP/1.1" 200 655
INFO 2024-02-02 11:42:30,185 basehttp 12168 24200 "GET /static/admin/img/selector-icons.svg HTTP/1.1" 200 3291
INFO 2024-02-02 11:42:30,187 basehttp 12168 19224 "GET /static/admin/img/icon-unknown-alt.svg HTTP/1.1" 200 655
INFO 2024-02-02 11:44:44,932 basehttp 12168 19224 "POST /admin/auth/user/2/change/ HTTP/1.1" 302 0
INFO 2024-02-02 11:44:44,991 basehttp 12168 19224 "GET /admin/auth/user/ HTTP/1.1" 200 13044
INFO 2024-02-02 11:44:45,035 basehttp 12168 24200 "GET /admin/jsi18n/ HTTP/1.1" 200 16066
INFO 2024-02-02 11:44:45,060 basehttp 12168 24200 "GET /static/admin/img/sorting-icons.svg HTTP/1.1" 200 1097
INFO 2024-02-02 11:49:05,893 basehttp 12168 8968 "GET /admin/mainapp/client/ HTTP/1.1" 200 15003
INFO 2024-02-02 11:49:05,929 basehttp 12168 10356 "GET /admin/jsi18n/ HTTP/1.1" 200 16066
INFO 2024-02-02 11:49:11,941 basehttp 12168 10356 "GET /admin/mainapp/order/ HTTP/1.1" 200 10529
INFO 2024-02-02 11:49:11,981 basehttp 12168 8968 "GET /admin/jsi18n/ HTTP/1.1" 200 16066
INFO 2024-02-02 11:49:35,959 basehttp 12168 8968 "GET /admin/mainapp/order/8/change/ HTTP/1.1" 200 13180
INFO 2024-02-02 11:49:35,994 basehttp 12168 10356 "GET /static/admin/img/icon-viewlink.svg HTTP/1.1" 200 581
INFO 2024-02-02 11:49:35,998 basehttp 12168 24472 "GET /admin/jsi18n/ HTTP/1.1" 200 16066
INFO 2024-02-02 11:50:20,375 basehttp 12168 24472 "GET /admin/auth/group/ HTTP/1.1" 200 8788
INFO 2024-02-02 11:50:20,410 basehttp 12168 10356 "GET /admin/jsi18n/ HTTP/1.1" 200 16066
INFO 2024-02-02 11:50:21,780 basehttp 12168 10356 "GET /admin/auth/user/ HTTP/1.1" 200 12823
INFO 2024-02-02 11:50:21,817 basehttp 12168 24472 "GET /admin/jsi18n/ HTTP/1.1" 200 16066
INFO 2024-02-02 11:50:25,739 basehttp 12168 24472 "GET /admin/mainapp/good/ HTTP/1.1" 200 15871
INFO 2024-02-02 11:50:25,777 basehttp 12168 10356 "GET /admin/jsi18n/ HTTP/1.1" 200 16066
INFO 2024-02-02 11:50:29,830 basehttp 12168 10356 "GET /admin/mainapp/good/5/change/ HTTP/1.1" 200 11748
INFO 2024-02-02 11:50:29,864 basehttp 12168 8968 "GET /admin/jsi18n/ HTTP/1.1" 200 16066
INFO 2024-02-02 11:50:29,878 basehttp 12168 24472 "GET /static/admin/js/collapse.js HTTP/1.1" 200 1803
INFO 2024-02-02 11:51:14,923 basehttp 12168 24472 "GET / HTTP/1.1" 200 117
INFO 2024-02-02 11:51:42,680 basehttp 12168 24472 "GET /add_good/ HTTP/1.1" 200 1216
INFO 2024-02-02 11:52:03,150 basehttp 12168 24472 "POST /add_good/ HTTP/1.1" 200 27
INFO 2024-02-02 11:52:10,432 basehttp 12168 24472 "GET /admin/ HTTP/1.1" 200 8043
INFO 2024-02-02 11:52:12,718 basehttp 12168 24472 "GET /admin/mainapp/good/ HTTP/1.1" 200 16983
INFO 2024-02-02 11:52:12,756 basehttp 12168 8968 "GET /admin/jsi18n/ HTTP/1.1" 200 16066
INFO 2024-02-06 21:27:17,161 autoreload 15080 26332 Watching for file changes with StatReloader
